INFO [2022-06-13 05:46:16,862] - [django.utils.autoreload:run_with_reloader:677] Watching for file changes with StatReloader
INFO [2022-06-13 06:16:59,675] - [django.utils.autoreload:run_with_reloader:677] Watching for file changes with StatReloader
WARNING [2022-06-13 06:17:02,276] - [django.request:log_response:241] Not Found: /
WARNING [2022-06-13 06:17:02,277] - [django.server:log_message:187] "GET / HTTP/1.1" 404 2891
WARNING [2022-06-13 06:17:02,435] - [django.request:log_response:241] Not Found: /favicon.ico
WARNING [2022-06-13 06:17:02,437] - [django.server:log_message:187] "GET /favicon.ico HTTP/1.1" 404 2942
WARNING [2022-06-13 06:17:05,521] - [django.request:log_response:241] Not Found: /
WARNING [2022-06-13 06:17:05,521] - [django.server:log_message:187] "GET / HTTP/1.1" 404 2891
INFO [2022-06-13 06:57:12,686] - [django.utils.autoreload:run_with_reloader:677] Watching for file changes with StatReloader
WARNING [2022-06-13 06:57:16,334] - [django.request:log_response:241] Not Found: /
WARNING [2022-06-13 06:57:16,335] - [django.server:log_message:187] "GET / HTTP/1.1" 404 2891
INFO [2022-06-13 07:06:47,819] - [django.utils.autoreload:run_with_reloader:677] Watching for file changes with StatReloader
INFO [2022-06-13 08:12:25,500] - [django.utils.autoreload:run_with_reloader:677] Watching for file changes with StatReloader
WARNING [2022-06-13 08:12:35,889] - [django.request:log_response:241] Not Found: /
WARNING [2022-06-13 08:12:35,890] - [django.server:log_message:187] "GET / HTTP/1.1" 404 2891
INFO [2022-06-13 08:13:18,057] - [django.utils.autoreload:trigger_reload:266] /home/wartinich/Projects/voice_generator/src/config/urls.py changed, reloading.
INFO [2022-06-13 08:13:18,627] - [django.utils.autoreload:run_with_reloader:677] Watching for file changes with StatReloader
INFO [2022-06-13 08:52:01,226] - [django.utils.autoreload:run_with_reloader:677] Watching for file changes with StatReloader
WARNING [2022-06-13 08:52:04,673] - [django.request:http_method_not_allowed:122] Method Not Allowed (GET): /login/
WARNING [2022-06-13 08:52:04,674] - [django.request:log_response:241] Method Not Allowed: /login/
WARNING [2022-06-13 08:52:04,674] - [django.server:log_message:187] "GET /login/ HTTP/1.1" 405 0
WARNING [2022-06-13 08:52:06,099] - [django.request:http_method_not_allowed:122] Method Not Allowed (GET): /login/
WARNING [2022-06-13 08:52:06,100] - [django.request:log_response:241] Method Not Allowed: /login/
WARNING [2022-06-13 08:52:06,108] - [django.server:log_message:187] "GET /login/ HTTP/1.1" 405 0
INFO [2022-06-13 08:52:30,094] - [django.utils.autoreload:trigger_reload:266] /home/wartinich/Projects/voice_generator/src/users/urls.py changed, reloading.
INFO [2022-06-13 08:52:30,741] - [django.utils.autoreload:run_with_reloader:677] Watching for file changes with StatReloader
INFO [2022-06-13 08:52:58,512] - [django.utils.autoreload:trigger_reload:266] /home/wartinich/Projects/voice_generator/src/users/views.py changed, reloading.
INFO [2022-06-13 08:52:59,222] - [django.utils.autoreload:run_with_reloader:677] Watching for file changes with StatReloader
WARNING [2022-06-13 08:53:04,118] - [django.request:log_response:241] Not Found: /login/
WARNING [2022-06-13 08:53:04,119] - [django.server:log_message:187] "GET /login/ HTTP/1.1" 404 3093
ERROR [2022-06-13 08:53:11,485] - [django.request:log_response:241] Internal Server Error: /login
Traceback (most recent call last):
  File "/home/wartinich/.local/lib/python3.10/site-packages/django/core/handlers/exception.py", line 55, in inner
    response = get_response(request)
  File "/home/wartinich/.local/lib/python3.10/site-packages/django/core/handlers/base.py", line 197, in _get_response
    response = wrapped_callback(request, *callback_args, **callback_kwargs)
  File "/home/wartinich/.local/lib/python3.10/site-packages/django/views/generic/base.py", line 84, in view
    return self.dispatch(request, *args, **kwargs)
  File "/home/wartinich/.local/lib/python3.10/site-packages/django/views/generic/base.py", line 119, in dispatch
    return handler(request, *args, **kwargs)
TypeError: LoginPageView.get() takes 1 positional argument but 2 were given
ERROR [2022-06-13 08:53:11,486] - [django.server:log_message:187] "GET /login HTTP/1.1" 500 70874
INFO [2022-06-13 08:53:33,410] - [django.utils.autoreload:trigger_reload:266] /home/wartinich/Projects/voice_generator/src/users/views.py changed, reloading.
INFO [2022-06-13 08:53:34,098] - [django.utils.autoreload:run_with_reloader:677] Watching for file changes with StatReloader
ERROR [2022-06-13 08:53:35,103] - [django.request:log_response:241] Internal Server Error: /login
Traceback (most recent call last):
  File "/home/wartinich/.local/lib/python3.10/site-packages/django/core/handlers/exception.py", line 55, in inner
    response = get_response(request)
  File "/home/wartinich/.local/lib/python3.10/site-packages/django/core/handlers/base.py", line 197, in _get_response
    response = wrapped_callback(request, *callback_args, **callback_kwargs)
  File "/home/wartinich/.local/lib/python3.10/site-packages/django/views/generic/base.py", line 84, in view
    return self.dispatch(request, *args, **kwargs)
  File "/home/wartinich/.local/lib/python3.10/site-packages/django/views/generic/base.py", line 119, in dispatch
    return handler(request, *args, **kwargs)
TypeError: LoginPageView.get() takes 1 positional argument but 2 were given
ERROR [2022-06-13 08:53:35,104] - [django.server:log_message:187] "GET /login HTTP/1.1" 500 70790
INFO [2022-06-13 08:55:29,749] - [django.utils.autoreload:trigger_reload:266] /home/wartinich/Projects/voice_generator/src/users/views.py changed, reloading.
INFO [2022-06-13 08:55:30,254] - [django.utils.autoreload:run_with_reloader:677] Watching for file changes with StatReloader
ERROR [2022-06-13 08:55:34,701] - [django.request:log_response:241] Internal Server Error: /login
Traceback (most recent call last):
  File "/home/wartinich/.local/lib/python3.10/site-packages/django/core/handlers/exception.py", line 55, in inner
    response = get_response(request)
  File "/home/wartinich/.local/lib/python3.10/site-packages/django/core/handlers/base.py", line 197, in _get_response
    response = wrapped_callback(request, *callback_args, **callback_kwargs)
  File "/home/wartinich/.local/lib/python3.10/site-packages/django/views/generic/base.py", line 84, in view
    return self.dispatch(request, *args, **kwargs)
  File "/home/wartinich/.local/lib/python3.10/site-packages/django/views/generic/base.py", line 119, in dispatch
    return handler(request, *args, **kwargs)
TypeError: LoginPageView.get() takes 1 positional argument but 2 were given
ERROR [2022-06-13 08:55:34,703] - [django.server:log_message:187] "GET /login HTTP/1.1" 500 70790
ERROR [2022-06-13 08:55:35,423] - [django.request:log_response:241] Internal Server Error: /login
Traceback (most recent call last):
  File "/home/wartinich/.local/lib/python3.10/site-packages/django/core/handlers/exception.py", line 55, in inner
    response = get_response(request)
  File "/home/wartinich/.local/lib/python3.10/site-packages/django/core/handlers/base.py", line 197, in _get_response
    response = wrapped_callback(request, *callback_args, **callback_kwargs)
  File "/home/wartinich/.local/lib/python3.10/site-packages/django/views/generic/base.py", line 84, in view
    return self.dispatch(request, *args, **kwargs)
  File "/home/wartinich/.local/lib/python3.10/site-packages/django/views/generic/base.py", line 119, in dispatch
    return handler(request, *args, **kwargs)
TypeError: LoginPageView.get() takes 1 positional argument but 2 were given
ERROR [2022-06-13 08:55:35,423] - [django.server:log_message:187] "GET /login HTTP/1.1" 500 70790
ERROR [2022-06-13 08:55:35,864] - [django.request:log_response:241] Internal Server Error: /login
Traceback (most recent call last):
  File "/home/wartinich/.local/lib/python3.10/site-packages/django/core/handlers/exception.py", line 55, in inner
    response = get_response(request)
  File "/home/wartinich/.local/lib/python3.10/site-packages/django/core/handlers/base.py", line 197, in _get_response
    response = wrapped_callback(request, *callback_args, **callback_kwargs)
  File "/home/wartinich/.local/lib/python3.10/site-packages/django/views/generic/base.py", line 84, in view
    return self.dispatch(request, *args, **kwargs)
  File "/home/wartinich/.local/lib/python3.10/site-packages/django/views/generic/base.py", line 119, in dispatch
    return handler(request, *args, **kwargs)
TypeError: LoginPageView.get() takes 1 positional argument but 2 were given
ERROR [2022-06-13 08:55:35,864] - [django.server:log_message:187] "GET /login HTTP/1.1" 500 70790
ERROR [2022-06-13 08:55:36,024] - [django.request:log_response:241] Internal Server Error: /login
Traceback (most recent call last):
  File "/home/wartinich/.local/lib/python3.10/site-packages/django/core/handlers/exception.py", line 55, in inner
    response = get_response(request)
  File "/home/wartinich/.local/lib/python3.10/site-packages/django/core/handlers/base.py", line 197, in _get_response
    response = wrapped_callback(request, *callback_args, **callback_kwargs)
  File "/home/wartinich/.local/lib/python3.10/site-packages/django/views/generic/base.py", line 84, in view
    return self.dispatch(request, *args, **kwargs)
  File "/home/wartinich/.local/lib/python3.10/site-packages/django/views/generic/base.py", line 119, in dispatch
    return handler(request, *args, **kwargs)
TypeError: LoginPageView.get() takes 1 positional argument but 2 were given
ERROR [2022-06-13 08:55:36,026] - [django.server:log_message:187] "GET /login HTTP/1.1" 500 70790
ERROR [2022-06-13 08:55:36,186] - [django.request:log_response:241] Internal Server Error: /login
Traceback (most recent call last):
  File "/home/wartinich/.local/lib/python3.10/site-packages/django/core/handlers/exception.py", line 55, in inner
    response = get_response(request)
  File "/home/wartinich/.local/lib/python3.10/site-packages/django/core/handlers/base.py", line 197, in _get_response
    response = wrapped_callback(request, *callback_args, **callback_kwargs)
  File "/home/wartinich/.local/lib/python3.10/site-packages/django/views/generic/base.py", line 84, in view
    return self.dispatch(request, *args, **kwargs)
  File "/home/wartinich/.local/lib/python3.10/site-packages/django/views/generic/base.py", line 119, in dispatch
    return handler(request, *args, **kwargs)
TypeError: LoginPageView.get() takes 1 positional argument but 2 were given
ERROR [2022-06-13 08:55:36,187] - [django.server:log_message:187] "GET /login HTTP/1.1" 500 70790
ERROR [2022-06-13 08:55:36,395] - [django.request:log_response:241] Internal Server Error: /login
Traceback (most recent call last):
  File "/home/wartinich/.local/lib/python3.10/site-packages/django/core/handlers/exception.py", line 55, in inner
    response = get_response(request)
  File "/home/wartinich/.local/lib/python3.10/site-packages/django/core/handlers/base.py", line 197, in _get_response
    response = wrapped_callback(request, *callback_args, **callback_kwargs)
  File "/home/wartinich/.local/lib/python3.10/site-packages/django/views/generic/base.py", line 84, in view
    return self.dispatch(request, *args, **kwargs)
  File "/home/wartinich/.local/lib/python3.10/site-packages/django/views/generic/base.py", line 119, in dispatch
    return handler(request, *args, **kwargs)
TypeError: LoginPageView.get() takes 1 positional argument but 2 were given
ERROR [2022-06-13 08:55:36,396] - [django.server:log_message:187] "GET /login HTTP/1.1" 500 70790
ERROR [2022-06-13 08:55:36,565] - [django.request:log_response:241] Internal Server Error: /login
Traceback (most recent call last):
  File "/home/wartinich/.local/lib/python3.10/site-packages/django/core/handlers/exception.py", line 55, in inner
    response = get_response(request)
  File "/home/wartinich/.local/lib/python3.10/site-packages/django/core/handlers/base.py", line 197, in _get_response
    response = wrapped_callback(request, *callback_args, **callback_kwargs)
  File "/home/wartinich/.local/lib/python3.10/site-packages/django/views/generic/base.py", line 84, in view
    return self.dispatch(request, *args, **kwargs)
  File "/home/wartinich/.local/lib/python3.10/site-packages/django/views/generic/base.py", line 119, in dispatch
    return handler(request, *args, **kwargs)
TypeError: LoginPageView.get() takes 1 positional argument but 2 were given
ERROR [2022-06-13 08:55:36,566] - [django.server:log_message:187] "GET /login HTTP/1.1" 500 70790
ERROR [2022-06-13 08:55:36,786] - [django.request:log_response:241] Internal Server Error: /login
Traceback (most recent call last):
  File "/home/wartinich/.local/lib/python3.10/site-packages/django/core/handlers/exception.py", line 55, in inner
    response = get_response(request)
  File "/home/wartinich/.local/lib/python3.10/site-packages/django/core/handlers/base.py", line 197, in _get_response
    response = wrapped_callback(request, *callback_args, **callback_kwargs)
  File "/home/wartinich/.local/lib/python3.10/site-packages/django/views/generic/base.py", line 84, in view
    return self.dispatch(request, *args, **kwargs)
  File "/home/wartinich/.local/lib/python3.10/site-packages/django/views/generic/base.py", line 119, in dispatch
    return handler(request, *args, **kwargs)
TypeError: LoginPageView.get() takes 1 positional argument but 2 were given
ERROR [2022-06-13 08:55:36,788] - [django.server:log_message:187] "GET /login HTTP/1.1" 500 70790
INFO [2022-06-13 08:57:21,882] - [django.utils.autoreload:trigger_reload:266] /home/wartinich/Projects/voice_generator/src/users/views.py changed, reloading.
INFO [2022-06-13 08:57:22,499] - [django.utils.autoreload:run_with_reloader:677] Watching for file changes with StatReloader
INFO [2022-06-13 08:57:45,151] - [django.utils.autoreload:trigger_reload:266] /home/wartinich/Projects/voice_generator/src/users/views.py changed, reloading.
INFO [2022-06-13 08:57:45,628] - [django.utils.autoreload:run_with_reloader:677] Watching for file changes with StatReloader
INFO [2022-06-13 08:58:17,449] - [django.utils.autoreload:trigger_reload:266] /home/wartinich/Projects/voice_generator/src/users/views.py changed, reloading.
INFO [2022-06-13 08:58:18,090] - [django.utils.autoreload:run_with_reloader:677] Watching for file changes with StatReloader
ERROR [2022-06-13 08:58:32,384] - [django.request:log_response:241] Internal Server Error: /login
Traceback (most recent call last):
  File "/home/wartinich/.local/lib/python3.10/site-packages/django/core/handlers/exception.py", line 55, in inner
    response = get_response(request)
  File "/home/wartinich/.local/lib/python3.10/site-packages/django/core/handlers/base.py", line 197, in _get_response
    response = wrapped_callback(request, *callback_args, **callback_kwargs)
  File "/home/wartinich/Projects/voice_generator/src/users/views.py", line 8, in login_page
    form = forms.LoginForm()
NameError: name 'forms' is not defined
ERROR [2022-06-13 08:58:32,386] - [django.server:log_message:187] "GET /login HTTP/1.1" 500 64983
INFO [2022-06-13 08:58:54,176] - [django.utils.autoreload:trigger_reload:266] /home/wartinich/Projects/voice_generator/src/users/views.py changed, reloading.
INFO [2022-06-13 08:58:54,733] - [django.utils.autoreload:run_with_reloader:677] Watching for file changes with StatReloader
INFO [2022-06-13 08:59:03,156] - [django.utils.autoreload:trigger_reload:266] /home/wartinich/Projects/voice_generator/src/users/views.py changed, reloading.
INFO [2022-06-13 08:59:03,690] - [django.utils.autoreload:run_with_reloader:677] Watching for file changes with StatReloader
INFO [2022-06-13 08:59:04,867] - [django.server:log_message:187] "GET /login HTTP/1.1" 200 382
INFO [2022-06-13 09:01:07,976] - [django.server:log_message:187] "GET /login HTTP/1.1" 200 1332
INFO [2022-06-13 09:06:59,127] - [django.utils.autoreload:trigger_reload:266] /home/wartinich/Projects/voice_generator/src/users/views.py changed, reloading.
INFO [2022-06-13 09:07:00,390] - [django.utils.autoreload:run_with_reloader:677] Watching for file changes with StatReloader
INFO [2022-06-13 09:09:31,105] - [django.utils.autoreload:trigger_reload:266] /home/wartinich/Projects/voice_generator/src/users/views.py changed, reloading.
INFO [2022-06-13 09:09:31,872] - [django.utils.autoreload:run_with_reloader:677] Watching for file changes with StatReloader
INFO [2022-06-13 09:09:36,385] - [django.utils.autoreload:trigger_reload:266] /home/wartinich/Projects/voice_generator/src/users/views.py changed, reloading.
INFO [2022-06-13 09:09:36,890] - [django.utils.autoreload:run_with_reloader:677] Watching for file changes with StatReloader
INFO [2022-06-13 09:09:41,263] - [django.utils.autoreload:trigger_reload:266] /home/wartinich/Projects/voice_generator/src/users/views.py changed, reloading.
INFO [2022-06-13 09:09:41,772] - [django.utils.autoreload:run_with_reloader:677] Watching for file changes with StatReloader
INFO [2022-06-13 09:09:59,513] - [django.utils.autoreload:trigger_reload:266] /home/wartinich/Projects/voice_generator/src/users/views.py changed, reloading.
INFO [2022-06-13 09:10:00,311] - [django.utils.autoreload:run_with_reloader:677] Watching for file changes with StatReloader
INFO [2022-06-13 09:10:15,176] - [django.utils.autoreload:trigger_reload:266] /home/wartinich/Projects/voice_generator/src/users/views.py changed, reloading.
INFO [2022-06-13 09:10:15,761] - [django.utils.autoreload:run_with_reloader:677] Watching for file changes with StatReloader
INFO [2022-06-13 09:10:18,200] - [django.utils.autoreload:trigger_reload:266] /home/wartinich/Projects/voice_generator/src/users/views.py changed, reloading.
INFO [2022-06-13 09:10:19,157] - [django.utils.autoreload:run_with_reloader:677] Watching for file changes with StatReloader
INFO [2022-06-13 09:10:20,526] - [django.utils.autoreload:trigger_reload:266] /home/wartinich/Projects/voice_generator/src/users/views.py changed, reloading.
INFO [2022-06-13 09:10:21,180] - [django.utils.autoreload:run_with_reloader:677] Watching for file changes with StatReloader
INFO [2022-06-13 09:10:42,008] - [django.utils.autoreload:trigger_reload:266] /home/wartinich/Projects/voice_generator/src/users/views.py changed, reloading.
INFO [2022-06-13 09:10:42,889] - [django.utils.autoreload:run_with_reloader:677] Watching for file changes with StatReloader
INFO [2022-06-13 09:11:22,381] - [django.utils.autoreload:trigger_reload:266] /home/wartinich/Projects/voice_generator/src/users/views.py changed, reloading.
INFO [2022-06-13 09:11:23,566] - [django.utils.autoreload:run_with_reloader:677] Watching for file changes with StatReloader
INFO [2022-06-13 09:11:49,926] - [django.utils.autoreload:trigger_reload:266] /home/wartinich/Projects/voice_generator/src/users/views.py changed, reloading.
INFO [2022-06-13 09:11:50,945] - [django.utils.autoreload:run_with_reloader:677] Watching for file changes with StatReloader
INFO [2022-06-13 09:11:59,515] - [django.utils.autoreload:trigger_reload:266] /home/wartinich/Projects/voice_generator/src/users/views.py changed, reloading.
INFO [2022-06-13 09:12:00,033] - [django.utils.autoreload:run_with_reloader:677] Watching for file changes with StatReloader
INFO [2022-06-13 09:12:17,657] - [django.utils.autoreload:trigger_reload:266] /home/wartinich/Projects/voice_generator/src/users/urls.py changed, reloading.
INFO [2022-06-13 09:12:18,194] - [django.utils.autoreload:run_with_reloader:677] Watching for file changes with StatReloader
ERROR [2022-06-13 09:12:20,135] - [django.request:log_response:241] Internal Server Error: /login
Traceback (most recent call last):
  File "/home/wartinich/.local/lib/python3.10/site-packages/django/core/handlers/exception.py", line 55, in inner
    response = get_response(request)
  File "/home/wartinich/.local/lib/python3.10/site-packages/django/core/handlers/base.py", line 197, in _get_response
    response = wrapped_callback(request, *callback_args, **callback_kwargs)
  File "/home/wartinich/.local/lib/python3.10/site-packages/django/views/generic/base.py", line 84, in view
    return self.dispatch(request, *args, **kwargs)
  File "/home/wartinich/.local/lib/python3.10/site-packages/django/views/generic/base.py", line 119, in dispatch
    return handler(request, *args, **kwargs)
TypeError: LoginPageView.get() takes 1 positional argument but 2 were given
ERROR [2022-06-13 09:12:20,136] - [django.server:log_message:187] "GET /login HTTP/1.1" 500 70790
ERROR [2022-06-13 09:12:21,096] - [django.request:log_response:241] Internal Server Error: /login
Traceback (most recent call last):
  File "/home/wartinich/.local/lib/python3.10/site-packages/django/core/handlers/exception.py", line 55, in inner
    response = get_response(request)
  File "/home/wartinich/.local/lib/python3.10/site-packages/django/core/handlers/base.py", line 197, in _get_response
    response = wrapped_callback(request, *callback_args, **callback_kwargs)
  File "/home/wartinich/.local/lib/python3.10/site-packages/django/views/generic/base.py", line 84, in view
    return self.dispatch(request, *args, **kwargs)
  File "/home/wartinich/.local/lib/python3.10/site-packages/django/views/generic/base.py", line 119, in dispatch
    return handler(request, *args, **kwargs)
TypeError: LoginPageView.get() takes 1 positional argument but 2 were given
ERROR [2022-06-13 09:12:21,097] - [django.server:log_message:187] "GET /login HTTP/1.1" 500 70790
ERROR [2022-06-13 09:12:21,484] - [django.request:log_response:241] Internal Server Error: /login
Traceback (most recent call last):
  File "/home/wartinich/.local/lib/python3.10/site-packages/django/core/handlers/exception.py", line 55, in inner
    response = get_response(request)
  File "/home/wartinich/.local/lib/python3.10/site-packages/django/core/handlers/base.py", line 197, in _get_response
    response = wrapped_callback(request, *callback_args, **callback_kwargs)
  File "/home/wartinich/.local/lib/python3.10/site-packages/django/views/generic/base.py", line 84, in view
    return self.dispatch(request, *args, **kwargs)
  File "/home/wartinich/.local/lib/python3.10/site-packages/django/views/generic/base.py", line 119, in dispatch
    return handler(request, *args, **kwargs)
TypeError: LoginPageView.get() takes 1 positional argument but 2 were given
ERROR [2022-06-13 09:12:21,484] - [django.server:log_message:187] "GET /login HTTP/1.1" 500 70790
ERROR [2022-06-13 09:12:21,649] - [django.request:log_response:241] Internal Server Error: /login
Traceback (most recent call last):
  File "/home/wartinich/.local/lib/python3.10/site-packages/django/core/handlers/exception.py", line 55, in inner
    response = get_response(request)
  File "/home/wartinich/.local/lib/python3.10/site-packages/django/core/handlers/base.py", line 197, in _get_response
    response = wrapped_callback(request, *callback_args, **callback_kwargs)
  File "/home/wartinich/.local/lib/python3.10/site-packages/django/views/generic/base.py", line 84, in view
    return self.dispatch(request, *args, **kwargs)
  File "/home/wartinich/.local/lib/python3.10/site-packages/django/views/generic/base.py", line 119, in dispatch
    return handler(request, *args, **kwargs)
TypeError: LoginPageView.get() takes 1 positional argument but 2 were given
ERROR [2022-06-13 09:12:21,651] - [django.server:log_message:187] "GET /login HTTP/1.1" 500 70790
ERROR [2022-06-13 09:12:21,827] - [django.request:log_response:241] Internal Server Error: /login
Traceback (most recent call last):
  File "/home/wartinich/.local/lib/python3.10/site-packages/django/core/handlers/exception.py", line 55, in inner
    response = get_response(request)
  File "/home/wartinich/.local/lib/python3.10/site-packages/django/core/handlers/base.py", line 197, in _get_response
    response = wrapped_callback(request, *callback_args, **callback_kwargs)
  File "/home/wartinich/.local/lib/python3.10/site-packages/django/views/generic/base.py", line 84, in view
    return self.dispatch(request, *args, **kwargs)
  File "/home/wartinich/.local/lib/python3.10/site-packages/django/views/generic/base.py", line 119, in dispatch
    return handler(request, *args, **kwargs)
TypeError: LoginPageView.get() takes 1 positional argument but 2 were given
ERROR [2022-06-13 09:12:21,828] - [django.server:log_message:187] "GET /login HTTP/1.1" 500 70790
INFO [2022-06-13 09:13:10,749] - [django.utils.autoreload:trigger_reload:266] /home/wartinich/Projects/voice_generator/src/users/views.py changed, reloading.
INFO [2022-06-13 09:13:11,323] - [django.utils.autoreload:run_with_reloader:677] Watching for file changes with StatReloader
INFO [2022-06-13 09:13:15,039] - [django.server:log_message:187] "GET /login HTTP/1.1" 200 1332
INFO [2022-06-13 09:15:00,164] - [django.utils.autoreload:trigger_reload:266] /home/wartinich/Projects/voice_generator/src/users/forms.py changed, reloading.
INFO [2022-06-13 09:15:00,829] - [django.utils.autoreload:run_with_reloader:677] Watching for file changes with StatReloader
INFO [2022-06-13 09:15:02,772] - [django.server:log_message:187] "GET /login HTTP/1.1" 200 1446
INFO [2022-06-13 09:16:43,242] - [django.utils.autoreload:trigger_reload:266] /home/wartinich/Projects/voice_generator/src/users/forms.py changed, reloading.
INFO [2022-06-13 09:16:43,819] - [django.utils.autoreload:run_with_reloader:677] Watching for file changes with StatReloader
INFO [2022-06-13 09:16:50,736] - [django.server:log_message:187] "GET /login HTTP/1.1" 200 1332
INFO [2022-06-13 09:19:45,870] - [django.utils.autoreload:trigger_reload:266] /home/wartinich/Projects/voice_generator/src/users/views.py changed, reloading.
INFO [2022-06-13 09:19:46,521] - [django.utils.autoreload:run_with_reloader:677] Watching for file changes with StatReloader
INFO [2022-06-13 09:19:54,963] - [django.utils.autoreload:trigger_reload:266] /home/wartinich/Projects/voice_generator/src/users/views.py changed, reloading.
INFO [2022-06-13 09:19:55,597] - [django.utils.autoreload:run_with_reloader:677] Watching for file changes with StatReloader
INFO [2022-06-13 09:19:59,940] - [django.server:log_message:187] "GET /login HTTP/1.1" 200 1332
INFO [2022-06-13 09:21:08,271] - [django.utils.autoreload:run_with_reloader:677] Watching for file changes with StatReloader
INFO [2022-06-13 09:22:49,658] - [django.utils.autoreload:trigger_reload:266] /home/wartinich/Projects/voice_generator/src/users/forms.py changed, reloading.
INFO [2022-06-13 09:22:50,201] - [django.utils.autoreload:run_with_reloader:677] Watching for file changes with StatReloader
INFO [2022-06-13 09:22:56,556] - [django.utils.autoreload:trigger_reload:266] /home/wartinich/Projects/voice_generator/src/users/forms.py changed, reloading.
INFO [2022-06-13 09:22:57,237] - [django.utils.autoreload:run_with_reloader:677] Watching for file changes with StatReloader
INFO [2022-06-13 09:23:08,631] - [django.utils.autoreload:trigger_reload:266] /home/wartinich/Projects/voice_generator/src/users/forms.py changed, reloading.
INFO [2022-06-13 09:23:09,148] - [django.utils.autoreload:run_with_reloader:677] Watching for file changes with StatReloader
INFO [2022-06-13 09:23:25,874] - [django.utils.autoreload:trigger_reload:266] /home/wartinich/Projects/voice_generator/src/users/forms.py changed, reloading.
INFO [2022-06-13 09:23:26,345] - [django.utils.autoreload:run_with_reloader:677] Watching for file changes with StatReloader
INFO [2022-06-13 09:23:53,026] - [django.utils.autoreload:trigger_reload:266] /home/wartinich/Projects/voice_generator/src/users/forms.py changed, reloading.
INFO [2022-06-13 09:23:53,540] - [django.utils.autoreload:run_with_reloader:677] Watching for file changes with StatReloader
INFO [2022-06-13 09:24:19,289] - [django.utils.autoreload:trigger_reload:266] /home/wartinich/Projects/voice_generator/src/users/forms.py changed, reloading.
INFO [2022-06-13 09:24:19,826] - [django.utils.autoreload:run_with_reloader:677] Watching for file changes with StatReloader
INFO [2022-06-13 09:27:11,537] - [django.utils.autoreload:trigger_reload:266] /home/wartinich/Projects/voice_generator/src/users/forms.py changed, reloading.
INFO [2022-06-13 09:27:12,157] - [django.utils.autoreload:run_with_reloader:677] Watching for file changes with StatReloader
INFO [2022-06-13 09:28:06,748] - [django.utils.autoreload:trigger_reload:266] /home/wartinich/Projects/voice_generator/src/users/views.py changed, reloading.
INFO [2022-06-13 09:28:07,209] - [django.utils.autoreload:run_with_reloader:677] Watching for file changes with StatReloader
INFO [2022-06-13 09:28:31,897] - [django.utils.autoreload:trigger_reload:266] /home/wartinich/Projects/voice_generator/src/users/views.py changed, reloading.
INFO [2022-06-13 09:28:32,401] - [django.utils.autoreload:run_with_reloader:677] Watching for file changes with StatReloader
INFO [2022-06-13 09:28:50,899] - [django.utils.autoreload:trigger_reload:266] /home/wartinich/Projects/voice_generator/src/users/views.py changed, reloading.
INFO [2022-06-13 09:28:51,426] - [django.utils.autoreload:run_with_reloader:677] Watching for file changes with StatReloader
INFO [2022-06-13 09:29:03,802] - [django.utils.autoreload:trigger_reload:266] /home/wartinich/Projects/voice_generator/src/users/views.py changed, reloading.
INFO [2022-06-13 09:29:04,616] - [django.utils.autoreload:run_with_reloader:677] Watching for file changes with StatReloader
INFO [2022-06-13 09:29:11,162] - [django.utils.autoreload:trigger_reload:266] /home/wartinich/Projects/voice_generator/src/users/views.py changed, reloading.
INFO [2022-06-13 09:29:12,002] - [django.utils.autoreload:run_with_reloader:677] Watching for file changes with StatReloader
INFO [2022-06-13 09:29:13,249] - [django.utils.autoreload:trigger_reload:266] /home/wartinich/Projects/voice_generator/src/users/views.py changed, reloading.
INFO [2022-06-13 09:29:14,208] - [django.utils.autoreload:run_with_reloader:677] Watching for file changes with StatReloader
INFO [2022-06-13 09:29:30,927] - [django.utils.autoreload:trigger_reload:266] /home/wartinich/Projects/voice_generator/src/users/views.py changed, reloading.
INFO [2022-06-13 09:29:31,626] - [django.utils.autoreload:run_with_reloader:677] Watching for file changes with StatReloader
INFO [2022-06-13 09:30:01,507] - [django.utils.autoreload:trigger_reload:266] /home/wartinich/Projects/voice_generator/src/users/views.py changed, reloading.
INFO [2022-06-13 09:30:02,312] - [django.utils.autoreload:run_with_reloader:677] Watching for file changes with StatReloader
INFO [2022-06-13 09:32:13,220] - [django.utils.autoreload:trigger_reload:266] /home/wartinich/Projects/voice_generator/src/users/urls.py changed, reloading.
INFO [2022-06-13 09:32:13,845] - [django.utils.autoreload:run_with_reloader:677] Watching for file changes with StatReloader
INFO [2022-06-13 09:32:27,118] - [django.server:log_message:187] "GET /swagger/ HTTP/1.1" 200 2232
INFO [2022-06-13 09:32:27,219] - [django.server:log_message:187] "GET /static/drf-yasg/style.css HTTP/1.1" 200 1047
INFO [2022-06-13 09:32:27,221] - [django.server:log_message:187] "GET /static/drf-yasg/insQ.min.js HTTP/1.1" 200 2093
INFO [2022-06-13 09:32:27,228] - [django.server:log_message:187] "GET /static/drf-yasg/url-polyfill.min.js HTTP/1.1" 200 6092
INFO [2022-06-13 09:32:27,231] - [django.server:log_message:187] "GET /static/drf-yasg/swagger-ui-init.js HTTP/1.1" 200 14715
INFO [2022-06-13 09:32:27,232] - [django.server:log_message:187] "GET /static/drf-yasg/immutable.min.js HTTP/1.1" 200 56904
INFO [2022-06-13 09:32:27,235] - [django.server:log_message:187] "GET /static/drf-yasg/swagger-ui-dist/swagger-ui.css HTTP/1.1" 200 143074
INFO [2022-06-13 09:32:27,239] - [django.server:log_message:187] "GET /static/drf-yasg/swagger-ui-dist/swagger-ui-standalone-preset.js HTTP/1.1" 200 329649
INFO [2022-06-13 09:32:27,241] - [django.server:log_message:187] "GET /static/drf-yasg/swagger-ui-dist/swagger-ui-bundle.js HTTP/1.1" 200 1038857
INFO [2022-06-13 09:32:30,329] - [django.server:log_message:187] "GET /sign_up HTTP/1.1" 200 1917
INFO [2022-06-13 09:39:04,624] - [django.utils.autoreload:trigger_reload:266] /home/wartinich/Projects/voice_generator/src/users/forms.py changed, reloading.
INFO [2022-06-13 09:39:05,139] - [django.utils.autoreload:run_with_reloader:677] Watching for file changes with StatReloader
INFO [2022-06-13 09:39:29,411] - [django.server:log_message:187] "GET /sign_up HTTP/1.1" 200 1917
INFO [2022-06-13 09:40:50,686] - [django.utils.autoreload:trigger_reload:266] /home/wartinich/Projects/voice_generator/src/users/forms.py changed, reloading.
INFO [2022-06-13 09:40:51,363] - [django.utils.autoreload:run_with_reloader:677] Watching for file changes with StatReloader
INFO [2022-06-13 09:41:04,901] - [django.utils.autoreload:trigger_reload:266] /home/wartinich/Projects/voice_generator/src/users/forms.py changed, reloading.
INFO [2022-06-13 09:41:05,503] - [django.utils.autoreload:run_with_reloader:677] Watching for file changes with StatReloader
INFO [2022-06-13 09:41:07,352] - [django.server:log_message:187] "GET /sign_up HTTP/1.1" 200 1750
INFO [2022-06-13 09:41:58,154] - [django.utils.autoreload:trigger_reload:266] /home/wartinich/Projects/voice_generator/src/users/forms.py changed, reloading.
INFO [2022-06-13 09:41:58,682] - [django.utils.autoreload:run_with_reloader:677] Watching for file changes with StatReloader
INFO [2022-06-13 09:42:01,205] - [django.server:log_message:187] "GET /sign_up HTTP/1.1" 200 1750
INFO [2022-06-13 09:42:08,378] - [django.utils.autoreload:trigger_reload:266] /home/wartinich/Projects/voice_generator/src/users/forms.py changed, reloading.
INFO [2022-06-13 09:42:09,019] - [django.utils.autoreload:run_with_reloader:677] Watching for file changes with StatReloader
INFO [2022-06-13 09:42:09,623] - [django.server:log_message:187] "GET /sign_up HTTP/1.1" 200 1917
INFO [2022-06-13 09:44:45,975] - [django.server:log_message:187] "GET /sign_up HTTP/1.1" 200 1943
INFO [2022-06-13 09:46:36,342] - [django.server:log_message:187] "GET /login HTTP/1.1" 200 950
INFO [2022-06-13 09:48:26,334] - [django.utils.autoreload:run_with_reloader:677] Watching for file changes with StatReloader
INFO [2022-06-13 09:51:21,893] - [django.utils.autoreload:trigger_reload:266] /home/wartinich/Projects/voice_generator/src/users/urls.py changed, reloading.
INFO [2022-06-13 09:51:22,349] - [django.utils.autoreload:run_with_reloader:677] Watching for file changes with StatReloader
INFO [2022-06-13 09:51:38,981] - [django.utils.autoreload:trigger_reload:266] /home/wartinich/Projects/voice_generator/src/users/urls.py changed, reloading.
INFO [2022-06-13 09:51:39,442] - [django.utils.autoreload:run_with_reloader:677] Watching for file changes with StatReloader
INFO [2022-06-13 09:52:29,136] - [django.utils.autoreload:trigger_reload:266] /home/wartinich/Projects/voice_generator/src/users/urls.py changed, reloading.
INFO [2022-06-13 09:52:29,707] - [django.utils.autoreload:run_with_reloader:677] Watching for file changes with StatReloader
INFO [2022-06-13 09:52:45,379] - [django.utils.autoreload:trigger_reload:266] /home/wartinich/Projects/voice_generator/src/users/urls.py changed, reloading.
INFO [2022-06-13 09:52:45,962] - [django.utils.autoreload:run_with_reloader:677] Watching for file changes with StatReloader
INFO [2022-06-13 09:53:51,941] - [django.utils.autoreload:run_with_reloader:677] Watching for file changes with StatReloader
INFO [2022-06-13 10:30:20,490] - [django.utils.autoreload:trigger_reload:266] /home/wartinich/Projects/voice_generator/src/config/urls.py changed, reloading.
INFO [2022-06-13 10:30:21,248] - [django.utils.autoreload:run_with_reloader:677] Watching for file changes with StatReloader
INFO [2022-06-13 10:30:39,704] - [django.utils.autoreload:trigger_reload:266] /home/wartinich/Projects/voice_generator/src/config/urls.py changed, reloading.
INFO [2022-06-13 10:30:40,181] - [django.utils.autoreload:run_with_reloader:677] Watching for file changes with StatReloader
INFO [2022-06-13 10:38:51,555] - [django.utils.autoreload:trigger_reload:266] /home/wartinich/Projects/voice_generator/src/config/settings.py changed, reloading.
INFO [2022-06-13 10:38:52,137] - [django.utils.autoreload:run_with_reloader:677] Watching for file changes with StatReloader
WARNING [2022-06-13 10:40:17,546] - [django.request:log_response:241] Not Found: /
WARNING [2022-06-13 10:40:17,546] - [django.server:log_message:187] "GET / HTTP/1.1" 404 3499
WARNING [2022-06-13 10:40:34,171] - [django.request:log_response:241] Not Found: /password_rest/
WARNING [2022-06-13 10:40:34,172] - [django.server:log_message:187] "GET /password_rest/ HTTP/1.1" 404 3559
WARNING [2022-06-13 10:40:40,524] - [django.request:log_response:241] Not Found: /password_reset/
WARNING [2022-06-13 10:40:40,524] - [django.server:log_message:187] "GET /password_reset/ HTTP/1.1" 404 3562
INFO [2022-06-13 10:41:45,485] - [django.server:log_message:187] "GET /swagger/ HTTP/1.1" 200 2232
INFO [2022-06-13 10:41:45,556] - [django.server:log_message:187] "GET /static/drf-yasg/style.css HTTP/1.1" 304 0
INFO [2022-06-13 10:41:45,560] - [django.server:log_message:187] "GET /static/drf-yasg/url-polyfill.min.js HTTP/1.1" 304 0
INFO [2022-06-13 10:41:45,561] - [django.server:log_message:187] "GET /static/drf-yasg/swagger-ui-dist/swagger-ui.css HTTP/1.1" 304 0
INFO [2022-06-13 10:41:45,567] - [django.server:log_message:187] "GET /static/drf-yasg/swagger-ui-dist/swagger-ui-standalone-preset.js HTTP/1.1" 304 0
INFO [2022-06-13 10:41:45,569] - [django.server:log_message:187] "GET /static/drf-yasg/swagger-ui-dist/swagger-ui-bundle.js HTTP/1.1" 304 0
INFO [2022-06-13 10:41:45,571] - [django.server:log_message:187] "GET /static/drf-yasg/swagger-ui-init.js HTTP/1.1" 304 0
INFO [2022-06-13 10:41:45,573] - [django.server:log_message:187] "GET /static/drf-yasg/immutable.min.js HTTP/1.1" 304 0
INFO [2022-06-13 10:41:45,573] - [django.server:log_message:187] "GET /static/drf-yasg/insQ.min.js HTTP/1.1" 304 0
INFO [2022-06-13 10:41:46,549] - [django.server:log_message:187] "GET /swagger/?format=openapi HTTP/1.1" 200 2302
INFO [2022-06-13 10:42:34,976] - [django.utils.autoreload:trigger_reload:266] /home/wartinich/Projects/voice_generator/src/config/urls.py changed, reloading.
INFO [2022-06-13 10:42:35,482] - [django.utils.autoreload:run_with_reloader:677] Watching for file changes with StatReloader
INFO [2022-06-13 10:43:11,491] - [django.utils.autoreload:trigger_reload:266] /home/wartinich/Projects/voice_generator/src/config/urls.py changed, reloading.
INFO [2022-06-13 10:43:12,203] - [django.utils.autoreload:run_with_reloader:677] Watching for file changes with StatReloader
INFO [2022-06-13 10:45:46,230] - [django.utils.autoreload:trigger_reload:266] /home/wartinich/Projects/voice_generator/src/config/urls.py changed, reloading.
INFO [2022-06-13 10:45:46,867] - [django.utils.autoreload:run_with_reloader:677] Watching for file changes with StatReloader
INFO [2022-06-13 10:48:13,076] - [django.utils.autoreload:trigger_reload:266] /home/wartinich/Projects/voice_generator/src/users/urls.py changed, reloading.
INFO [2022-06-13 10:48:13,806] - [django.utils.autoreload:run_with_reloader:677] Watching for file changes with StatReloader
INFO [2022-06-13 10:48:37,478] - [django.utils.autoreload:trigger_reload:266] /home/wartinich/Projects/voice_generator/src/users/urls.py changed, reloading.
INFO [2022-06-13 10:48:38,050] - [django.utils.autoreload:run_with_reloader:677] Watching for file changes with StatReloader
WARNING [2022-06-13 10:48:45,003] - [django.request:log_response:241] Not Found: /password_reset/
WARNING [2022-06-13 10:48:45,006] - [django.server:log_message:187] "GET /password_reset/ HTTP/1.1" 404 4274
ERROR [2022-06-13 10:48:56,926] - [django.request:log_response:241] Internal Server Error: /password-reset/
Traceback (most recent call last):
  File "/home/wartinich/.local/lib/python3.10/site-packages/django/core/handlers/exception.py", line 55, in inner
    response = get_response(request)
  File "/home/wartinich/.local/lib/python3.10/site-packages/django/core/handlers/base.py", line 220, in _get_response
    response = response.render()
  File "/home/wartinich/.local/lib/python3.10/site-packages/django/template/response.py", line 114, in render
    self.content = self.rendered_content
  File "/home/wartinich/.local/lib/python3.10/site-packages/django/template/response.py", line 90, in rendered_content
    template = self.resolve_template(self.template_name)
  File "/home/wartinich/.local/lib/python3.10/site-packages/django/template/response.py", line 72, in resolve_template
    return select_template(template, using=self.using)
  File "/home/wartinich/.local/lib/python3.10/site-packages/django/template/loader.py", line 47, in select_template
    raise TemplateDoesNotExist(", ".join(template_name_list), chain=chain)
django.template.exceptions.TemplateDoesNotExist: registration/password_reset.html
ERROR [2022-06-13 10:48:56,928] - [django.server:log_message:187] "GET /password-reset/ HTTP/1.1" 500 81600
INFO [2022-06-13 10:49:41,881] - [django.utils.autoreload:trigger_reload:266] /home/wartinich/Projects/voice_generator/src/users/urls.py changed, reloading.
INFO [2022-06-13 10:49:42,368] - [django.utils.autoreload:run_with_reloader:677] Watching for file changes with StatReloader
INFO [2022-06-13 10:49:44,039] - [django.server:log_message:187] "GET /password-reset/ HTTP/1.1" 200 787
INFO [2022-06-13 10:51:25,594] - [django.utils.autoreload:trigger_reload:266] /home/wartinich/Projects/voice_generator/src/users/models.py changed, reloading.
INFO [2022-06-13 10:51:26,078] - [django.utils.autoreload:run_with_reloader:677] Watching for file changes with StatReloader
INFO [2022-06-13 10:52:36,629] - [django.server:log_message:187] "GET /login/ HTTP/1.1" 200 950
INFO [2022-06-13 10:53:00,330] - [django.server:log_message:187] "POST /login/ HTTP/1.1" 200 1011
WARNING [2022-06-13 10:53:28,593] - [django.request:log_response:241] Not Found: /reset-password/
WARNING [2022-06-13 10:53:28,594] - [django.server:log_message:187] "GET /reset-password/ HTTP/1.1" 404 4274
INFO [2022-06-13 10:53:40,845] - [django.server:log_message:187] "GET /password-reset/ HTTP/1.1" 200 787
ERROR [2022-06-13 10:53:58,219] - [django.request:log_response:241] Internal Server Error: /password-reset/
Traceback (most recent call last):
  File "/home/wartinich/.local/lib/python3.10/site-packages/django/core/handlers/exception.py", line 55, in inner
    response = get_response(request)
  File "/home/wartinich/.local/lib/python3.10/site-packages/django/core/handlers/base.py", line 197, in _get_response
    response = wrapped_callback(request, *callback_args, **callback_kwargs)
  File "/home/wartinich/.local/lib/python3.10/site-packages/django/views/generic/base.py", line 84, in view
    return self.dispatch(request, *args, **kwargs)
  File "/home/wartinich/.local/lib/python3.10/site-packages/django/utils/decorators.py", line 46, in _wrapper
    return bound_method(*args, **kwargs)
  File "/home/wartinich/.local/lib/python3.10/site-packages/django/utils/decorators.py", line 133, in _wrapped_view
    response = view_func(request, *args, **kwargs)
  File "/home/wartinich/.local/lib/python3.10/site-packages/django/contrib/auth/views.py", line 232, in dispatch
    return super().dispatch(*args, **kwargs)
  File "/home/wartinich/.local/lib/python3.10/site-packages/django/views/generic/base.py", line 119, in dispatch
    return handler(request, *args, **kwargs)
  File "/home/wartinich/.local/lib/python3.10/site-packages/django/views/generic/edit.py", line 153, in post
    return self.form_valid(form)
  File "/home/wartinich/.local/lib/python3.10/site-packages/django/contrib/auth/views.py", line 245, in form_valid
    form.save(**opts)
  File "/home/wartinich/.local/lib/python3.10/site-packages/django/contrib/auth/forms.py", line 343, in save
    self.send_mail(
  File "/home/wartinich/.local/lib/python3.10/site-packages/django/contrib/auth/forms.py", line 284, in send_mail
    email_message.send()
  File "/home/wartinich/.local/lib/python3.10/site-packages/django/core/mail/message.py", line 298, in send
    return self.get_connection(fail_silently).send_messages([self])
  File "/home/wartinich/.local/lib/python3.10/site-packages/django/core/mail/backends/smtp.py", line 131, in send_messages
    sent = self._send(message)
  File "/home/wartinich/.local/lib/python3.10/site-packages/django/core/mail/backends/smtp.py", line 149, in _send
    self.connection.sendmail(
  File "/usr/local/lib/python3.10/smtplib.py", line 887, in sendmail
    raise SMTPSenderRefused(code, resp, from_addr)
smtplib.SMTPSenderRefused: (530, b'5.7.0 Authentication Required. Learn more at\n5.7.0  https://support.google.com/mail/?p=WantAuthError r27-20020ac25a5b000000b0047255d2118esm939652lfn.189 - gsmtp', 'webmaster@localhost')
ERROR [2022-06-13 10:53:58,221] - [django.server:log_message:187] "POST /password-reset/ HTTP/1.1" 500 130208
INFO [2022-06-13 10:55:57,166] - [django.utils.autoreload:trigger_reload:266] /home/wartinich/Projects/voice_generator/src/users/views.py changed, reloading.
INFO [2022-06-13 10:55:57,899] - [django.utils.autoreload:run_with_reloader:677] Watching for file changes with StatReloader
INFO [2022-06-13 10:56:05,915] - [django.server:log_message:187] "GET /login/ HTTP/1.1" 200 950
ERROR [2022-06-13 10:56:23,219] - [django.request:log_response:241] Internal Server Error: /login/
Traceback (most recent call last):
  File "/home/wartinich/.local/lib/python3.10/site-packages/django/core/handlers/exception.py", line 55, in inner
    response = get_response(request)
  File "/home/wartinich/.local/lib/python3.10/site-packages/django/core/handlers/base.py", line 197, in _get_response
    response = wrapped_callback(request, *callback_args, **callback_kwargs)
  File "/home/wartinich/.local/lib/python3.10/site-packages/django/views/generic/base.py", line 84, in view
    return self.dispatch(request, *args, **kwargs)
  File "/home/wartinich/.local/lib/python3.10/site-packages/django/views/generic/base.py", line 119, in dispatch
    return handler(request, *args, **kwargs)
  File "/home/wartinich/Projects/voice_generator/src/users/views.py", line 46, in post
    'message': message
UnboundLocalError: local variable 'message' referenced before assignment
ERROR [2022-06-13 10:56:23,221] - [django.server:log_message:187] "POST /login/ HTTP/1.1" 500 76483
INFO [2022-06-13 10:56:47,938] - [django.utils.autoreload:trigger_reload:266] /home/wartinich/Projects/voice_generator/src/users/views.py changed, reloading.
INFO [2022-06-13 10:56:48,431] - [django.utils.autoreload:run_with_reloader:677] Watching for file changes with StatReloader
ERROR [2022-06-13 10:56:51,007] - [django.request:log_response:241] Internal Server Error: /login/
Traceback (most recent call last):
  File "/home/wartinich/.local/lib/python3.10/site-packages/django/core/handlers/exception.py", line 55, in inner
    response = get_response(request)
  File "/home/wartinich/.local/lib/python3.10/site-packages/django/core/handlers/base.py", line 197, in _get_response
    response = wrapped_callback(request, *callback_args, **callback_kwargs)
  File "/home/wartinich/.local/lib/python3.10/site-packages/django/views/generic/base.py", line 84, in view
    return self.dispatch(request, *args, **kwargs)
  File "/home/wartinich/.local/lib/python3.10/site-packages/django/views/generic/base.py", line 119, in dispatch
    return handler(request, *args, **kwargs)
  File "/home/wartinich/Projects/voice_generator/src/users/views.py", line 46, in post
    'message': message
NameError: name 'message' is not defined
ERROR [2022-06-13 10:56:51,009] - [django.server:log_message:187] "POST /login/ HTTP/1.1" 500 76339
INFO [2022-06-13 10:56:59,131] - [django.utils.autoreload:trigger_reload:266] /home/wartinich/Projects/voice_generator/src/users/views.py changed, reloading.
INFO [2022-06-13 10:56:59,835] - [django.utils.autoreload:run_with_reloader:677] Watching for file changes with StatReloader
INFO [2022-06-13 10:57:01,144] - [django.server:log_message:187] "POST /login/ HTTP/1.1" 200 998
INFO [2022-06-13 10:58:11,652] - [django.utils.autoreload:trigger_reload:266] /home/wartinich/Projects/voice_generator/src/users/views.py changed, reloading.
INFO [2022-06-13 10:58:12,242] - [django.utils.autoreload:run_with_reloader:677] Watching for file changes with StatReloader
INFO [2022-06-13 10:58:17,196] - [django.server:log_message:187] "POST /login/ HTTP/1.1" 200 998
INFO [2022-06-13 11:00:51,144] - [django.utils.autoreload:trigger_reload:266] /home/wartinich/Projects/voice_generator/src/users/views.py changed, reloading.
INFO [2022-06-13 11:00:51,710] - [django.utils.autoreload:run_with_reloader:677] Watching for file changes with StatReloader
INFO [2022-06-13 11:00:54,127] - [django.server:log_message:187] "POST /login/ HTTP/1.1" 200 998
INFO [2022-06-13 11:00:58,247] - [django.server:log_message:187] "POST /login/ HTTP/1.1" 200 998
INFO [2022-06-13 11:01:40,999] - [django.server:log_message:187] "POST /login/ HTTP/1.1" 200 998
INFO [2022-06-13 11:01:59,856] - [django.server:log_message:187] "GET /swagger/ HTTP/1.1" 200 2232
INFO [2022-06-13 11:02:02,884] - [django.server:log_message:187] "GET /sign_up HTTP/1.1" 301 0
INFO [2022-06-13 11:02:02,911] - [django.server:log_message:187] "GET /sign_up/ HTTP/1.1" 200 1943
INFO [2022-06-13 11:02:36,556] - [django.server:log_message:187] "POST /sign_up/ HTTP/1.1" 200 2099
INFO [2022-06-13 11:02:42,722] - [django.server:log_message:187] "GET /admin HTTP/1.1" 301 0
INFO [2022-06-13 11:02:42,731] - [django.server:log_message:187] "GET /admin/ HTTP/1.1" 302 0
INFO [2022-06-13 11:02:42,750] - [django.server:log_message:187] "GET /admin/login/?next=/admin/ HTTP/1.1" 200 2215
INFO [2022-06-13 11:02:42,842] - [django.server:log_message:187] "GET /static/admin/css/nav_sidebar.css HTTP/1.1" 200 2616
INFO [2022-06-13 11:02:42,842] - [django.server:log_message:187] "GET /static/admin/css/base.css HTTP/1.1" 200 19513
INFO [2022-06-13 11:02:42,842] - [django.server:log_message:187] "GET /static/admin/js/nav_sidebar.js HTTP/1.1" 200 3763
INFO [2022-06-13 11:02:42,843] - [django.server:log_message:187] "GET /static/admin/css/login.css HTTP/1.1" 200 954
INFO [2022-06-13 11:02:42,844] - [django.server:log_message:187] "GET /static/admin/css/responsive.css HTTP/1.1" 200 18575
INFO [2022-06-13 11:02:43,354] - [django.server:log_message:187] "GET /admin/ HTTP/1.1" 302 0
INFO [2022-06-13 11:02:43,378] - [django.server:log_message:187] "GET /admin/login/?next=/admin/ HTTP/1.1" 200 2215
INFO [2022-06-13 11:02:43,406] - [django.server:log_message:187] "GET /static/admin/css/fonts.css HTTP/1.1" 200 423
INFO [2022-06-13 11:02:43,455] - [django.server:log_message:187] "GET /static/admin/fonts/Roboto-Regular-webfont.woff HTTP/1.1" 200 85876
INFO [2022-06-13 11:02:43,455] - [django.server:log_message:187] "GET /static/admin/fonts/Roboto-Light-webfont.woff HTTP/1.1" 200 85692
INFO [2022-06-13 11:02:45,155] - [django.server:log_message:187] "POST /admin/login/?next=/admin/ HTTP/1.1" 302 0
INFO [2022-06-13 11:02:45,177] - [django.server:log_message:187] "GET /admin/ HTTP/1.1" 200 2923
INFO [2022-06-13 11:02:45,240] - [django.server:log_message:187] "GET /static/admin/css/dashboard.css HTTP/1.1" 200 380
INFO [2022-06-13 11:02:45,257] - [django.server:log_message:187] "GET /static/admin/img/icon-changelink.svg HTTP/1.1" 200 380
INFO [2022-06-13 11:02:45,257] - [django.server:log_message:187] "GET /static/admin/img/icon-addlink.svg HTTP/1.1" 200 331
INFO [2022-06-13 11:02:45,281] - [django.server:log_message:187] "GET /static/admin/fonts/Roboto-Bold-webfont.woff HTTP/1.1" 200 86184
WARNING [2022-06-13 11:04:32,327] - [django.request:log_response:241] Not Found: /pass/
WARNING [2022-06-13 11:04:32,329] - [django.server:log_message:187] "GET /pass/ HTTP/1.1" 404 4244
INFO [2022-06-13 11:04:37,860] - [django.server:log_message:187] "GET /password-reset/ HTTP/1.1" 200 787
ERROR [2022-06-13 11:04:54,346] - [django.request:log_response:241] Internal Server Error: /password-reset/
Traceback (most recent call last):
  File "/home/wartinich/.local/lib/python3.10/site-packages/django/core/handlers/exception.py", line 55, in inner
    response = get_response(request)
  File "/home/wartinich/.local/lib/python3.10/site-packages/django/core/handlers/base.py", line 197, in _get_response
    response = wrapped_callback(request, *callback_args, **callback_kwargs)
  File "/home/wartinich/.local/lib/python3.10/site-packages/django/views/generic/base.py", line 84, in view
    return self.dispatch(request, *args, **kwargs)
  File "/home/wartinich/.local/lib/python3.10/site-packages/django/utils/decorators.py", line 46, in _wrapper
    return bound_method(*args, **kwargs)
  File "/home/wartinich/.local/lib/python3.10/site-packages/django/utils/decorators.py", line 133, in _wrapped_view
    response = view_func(request, *args, **kwargs)
  File "/home/wartinich/.local/lib/python3.10/site-packages/django/contrib/auth/views.py", line 232, in dispatch
    return super().dispatch(*args, **kwargs)
  File "/home/wartinich/.local/lib/python3.10/site-packages/django/views/generic/base.py", line 119, in dispatch
    return handler(request, *args, **kwargs)
  File "/home/wartinich/.local/lib/python3.10/site-packages/django/views/generic/edit.py", line 153, in post
    return self.form_valid(form)
  File "/home/wartinich/.local/lib/python3.10/site-packages/django/contrib/auth/views.py", line 245, in form_valid
    form.save(**opts)
  File "/home/wartinich/.local/lib/python3.10/site-packages/django/contrib/auth/forms.py", line 343, in save
    self.send_mail(
  File "/home/wartinich/.local/lib/python3.10/site-packages/django/contrib/auth/forms.py", line 284, in send_mail
    email_message.send()
  File "/home/wartinich/.local/lib/python3.10/site-packages/django/core/mail/message.py", line 298, in send
    return self.get_connection(fail_silently).send_messages([self])
  File "/home/wartinich/.local/lib/python3.10/site-packages/django/core/mail/backends/smtp.py", line 131, in send_messages
    sent = self._send(message)
  File "/home/wartinich/.local/lib/python3.10/site-packages/django/core/mail/backends/smtp.py", line 149, in _send
    self.connection.sendmail(
  File "/usr/local/lib/python3.10/smtplib.py", line 887, in sendmail
    raise SMTPSenderRefused(code, resp, from_addr)
smtplib.SMTPSenderRefused: (530, b'5.7.0 Authentication Required. Learn more at\n5.7.0  https://support.google.com/mail/?p=WantAuthError w14-20020a05651234ce00b00477b11144e9sm947237lfr.66 - gsmtp', 'webmaster@localhost')
ERROR [2022-06-13 11:04:54,347] - [django.server:log_message:187] "POST /password-reset/ HTTP/1.1" 500 130418
INFO [2022-06-13 11:06:05,799] - [django.utils.autoreload:trigger_reload:266] /home/wartinich/Projects/voice_generator/src/config/settings.py changed, reloading.
INFO [2022-06-13 11:06:06,415] - [django.utils.autoreload:run_with_reloader:677] Watching for file changes with StatReloader
ERROR [2022-06-13 11:06:10,637] - [django.request:log_response:241] Internal Server Error: /password-reset/
Traceback (most recent call last):
  File "/home/wartinich/.local/lib/python3.10/site-packages/django/core/handlers/exception.py", line 55, in inner
    response = get_response(request)
  File "/home/wartinich/.local/lib/python3.10/site-packages/django/core/handlers/base.py", line 197, in _get_response
    response = wrapped_callback(request, *callback_args, **callback_kwargs)
  File "/home/wartinich/.local/lib/python3.10/site-packages/django/views/generic/base.py", line 84, in view
    return self.dispatch(request, *args, **kwargs)
  File "/home/wartinich/.local/lib/python3.10/site-packages/django/utils/decorators.py", line 46, in _wrapper
    return bound_method(*args, **kwargs)
  File "/home/wartinich/.local/lib/python3.10/site-packages/django/utils/decorators.py", line 133, in _wrapped_view
    response = view_func(request, *args, **kwargs)
  File "/home/wartinich/.local/lib/python3.10/site-packages/django/contrib/auth/views.py", line 232, in dispatch
    return super().dispatch(*args, **kwargs)
  File "/home/wartinich/.local/lib/python3.10/site-packages/django/views/generic/base.py", line 119, in dispatch
    return handler(request, *args, **kwargs)
  File "/home/wartinich/.local/lib/python3.10/site-packages/django/views/generic/edit.py", line 153, in post
    return self.form_valid(form)
  File "/home/wartinich/.local/lib/python3.10/site-packages/django/contrib/auth/views.py", line 245, in form_valid
    form.save(**opts)
  File "/home/wartinich/.local/lib/python3.10/site-packages/django/contrib/auth/forms.py", line 343, in save
    self.send_mail(
  File "/home/wartinich/.local/lib/python3.10/site-packages/django/contrib/auth/forms.py", line 284, in send_mail
    email_message.send()
  File "/home/wartinich/.local/lib/python3.10/site-packages/django/core/mail/message.py", line 298, in send
    return self.get_connection(fail_silently).send_messages([self])
  File "/home/wartinich/.local/lib/python3.10/site-packages/django/core/mail/message.py", line 255, in get_connection
    self.connection = get_connection(fail_silently=fail_silently)
  File "/home/wartinich/.local/lib/python3.10/site-packages/django/core/mail/__init__.py", line 51, in get_connection
    return klass(fail_silently=fail_silently, **kwds)
  File "/home/wartinich/.local/lib/python3.10/site-packages/django/core/mail/backends/smtp.py", line 46, in __init__
    raise ValueError(
ValueError: EMAIL_USE_TLS/EMAIL_USE_SSL are mutually exclusive, so only set one of those settings to True.
ERROR [2022-06-13 11:06:10,638] - [django.server:log_message:187] "POST /password-reset/ HTTP/1.1" 500 128602
INFO [2022-06-13 11:06:42,641] - [django.utils.autoreload:trigger_reload:266] /home/wartinich/Projects/voice_generator/src/config/settings.py changed, reloading.
INFO [2022-06-13 11:06:43,288] - [django.utils.autoreload:run_with_reloader:677] Watching for file changes with StatReloader
ERROR [2022-06-13 11:06:46,620] - [django.request:log_response:241] Internal Server Error: /password-reset/
Traceback (most recent call last):
  File "/home/wartinich/.local/lib/python3.10/site-packages/django/core/handlers/exception.py", line 55, in inner
    response = get_response(request)
  File "/home/wartinich/.local/lib/python3.10/site-packages/django/core/handlers/base.py", line 197, in _get_response
    response = wrapped_callback(request, *callback_args, **callback_kwargs)
  File "/home/wartinich/.local/lib/python3.10/site-packages/django/views/generic/base.py", line 84, in view
    return self.dispatch(request, *args, **kwargs)
  File "/home/wartinich/.local/lib/python3.10/site-packages/django/utils/decorators.py", line 46, in _wrapper
    return bound_method(*args, **kwargs)
  File "/home/wartinich/.local/lib/python3.10/site-packages/django/utils/decorators.py", line 133, in _wrapped_view
    response = view_func(request, *args, **kwargs)
  File "/home/wartinich/.local/lib/python3.10/site-packages/django/contrib/auth/views.py", line 232, in dispatch
    return super().dispatch(*args, **kwargs)
  File "/home/wartinich/.local/lib/python3.10/site-packages/django/views/generic/base.py", line 119, in dispatch
    return handler(request, *args, **kwargs)
  File "/home/wartinich/.local/lib/python3.10/site-packages/django/views/generic/edit.py", line 153, in post
    return self.form_valid(form)
  File "/home/wartinich/.local/lib/python3.10/site-packages/django/contrib/auth/views.py", line 245, in form_valid
    form.save(**opts)
  File "/home/wartinich/.local/lib/python3.10/site-packages/django/contrib/auth/forms.py", line 343, in save
    self.send_mail(
  File "/home/wartinich/.local/lib/python3.10/site-packages/django/contrib/auth/forms.py", line 284, in send_mail
    email_message.send()
  File "/home/wartinich/.local/lib/python3.10/site-packages/django/core/mail/message.py", line 298, in send
    return self.get_connection(fail_silently).send_messages([self])
  File "/home/wartinich/.local/lib/python3.10/site-packages/django/core/mail/message.py", line 255, in get_connection
    self.connection = get_connection(fail_silently=fail_silently)
  File "/home/wartinich/.local/lib/python3.10/site-packages/django/core/mail/__init__.py", line 51, in get_connection
    return klass(fail_silently=fail_silently, **kwds)
  File "/home/wartinich/.local/lib/python3.10/site-packages/django/core/mail/backends/smtp.py", line 46, in __init__
    raise ValueError(
ValueError: EMAIL_USE_TLS/EMAIL_USE_SSL are mutually exclusive, so only set one of those settings to True.
ERROR [2022-06-13 11:06:46,621] - [django.server:log_message:187] "POST /password-reset/ HTTP/1.1" 500 128322
INFO [2022-06-13 11:08:28,311] - [django.utils.autoreload:run_with_reloader:677] Watching for file changes with StatReloader
ERROR [2022-06-13 11:08:32,464] - [django.request:log_response:241] Internal Server Error: /password-reset/
Traceback (most recent call last):
  File "/home/wartinich/.local/lib/python3.10/site-packages/django/core/handlers/exception.py", line 55, in inner
    response = get_response(request)
  File "/home/wartinich/.local/lib/python3.10/site-packages/django/core/handlers/base.py", line 197, in _get_response
    response = wrapped_callback(request, *callback_args, **callback_kwargs)
  File "/home/wartinich/.local/lib/python3.10/site-packages/django/views/generic/base.py", line 84, in view
    return self.dispatch(request, *args, **kwargs)
  File "/home/wartinich/.local/lib/python3.10/site-packages/django/utils/decorators.py", line 46, in _wrapper
    return bound_method(*args, **kwargs)
  File "/home/wartinich/.local/lib/python3.10/site-packages/django/utils/decorators.py", line 133, in _wrapped_view
    response = view_func(request, *args, **kwargs)
  File "/home/wartinich/.local/lib/python3.10/site-packages/django/contrib/auth/views.py", line 232, in dispatch
    return super().dispatch(*args, **kwargs)
  File "/home/wartinich/.local/lib/python3.10/site-packages/django/views/generic/base.py", line 119, in dispatch
    return handler(request, *args, **kwargs)
  File "/home/wartinich/.local/lib/python3.10/site-packages/django/views/generic/edit.py", line 153, in post
    return self.form_valid(form)
  File "/home/wartinich/.local/lib/python3.10/site-packages/django/contrib/auth/views.py", line 245, in form_valid
    form.save(**opts)
  File "/home/wartinich/.local/lib/python3.10/site-packages/django/contrib/auth/forms.py", line 343, in save
    self.send_mail(
  File "/home/wartinich/.local/lib/python3.10/site-packages/django/contrib/auth/forms.py", line 284, in send_mail
    email_message.send()
  File "/home/wartinich/.local/lib/python3.10/site-packages/django/core/mail/message.py", line 298, in send
    return self.get_connection(fail_silently).send_messages([self])
  File "/home/wartinich/.local/lib/python3.10/site-packages/django/core/mail/backends/smtp.py", line 124, in send_messages
    new_conn_created = self.open()
  File "/home/wartinich/.local/lib/python3.10/site-packages/django/core/mail/backends/smtp.py", line 80, in open
    self.connection = self.connection_class(
  File "/usr/local/lib/python3.10/smtplib.py", line 1050, in __init__
    SMTP.__init__(self, host, port, local_hostname, timeout,
  File "/usr/local/lib/python3.10/smtplib.py", line 255, in __init__
    (code, msg) = self.connect(host, port)
  File "/usr/local/lib/python3.10/smtplib.py", line 341, in connect
    self.sock = self._get_socket(host, port, self.timeout)
  File "/usr/local/lib/python3.10/smtplib.py", line 1057, in _get_socket
    new_socket = self.context.wrap_socket(new_socket,
  File "/usr/local/lib/python3.10/ssl.py", line 512, in wrap_socket
    return self.sslsocket_class._create(
  File "/usr/local/lib/python3.10/ssl.py", line 1070, in _create
    self.do_handshake()
  File "/usr/local/lib/python3.10/ssl.py", line 1341, in do_handshake
    self._sslobj.do_handshake()
ssl.SSLError: [SSL: WRONG_VERSION_NUMBER] wrong version number (_ssl.c:997)
ERROR [2022-06-13 11:08:32,466] - [django.server:log_message:187] "POST /password-reset/ HTTP/1.1" 500 155268
ERROR [2022-06-13 11:09:24,117] - [django.request:log_response:241] Internal Server Error: /password-reset/
Traceback (most recent call last):
  File "/home/wartinich/.local/lib/python3.10/site-packages/django/core/handlers/exception.py", line 55, in inner
    response = get_response(request)
  File "/home/wartinich/.local/lib/python3.10/site-packages/django/core/handlers/base.py", line 197, in _get_response
    response = wrapped_callback(request, *callback_args, **callback_kwargs)
  File "/home/wartinich/.local/lib/python3.10/site-packages/django/views/generic/base.py", line 84, in view
    return self.dispatch(request, *args, **kwargs)
  File "/home/wartinich/.local/lib/python3.10/site-packages/django/utils/decorators.py", line 46, in _wrapper
    return bound_method(*args, **kwargs)
  File "/home/wartinich/.local/lib/python3.10/site-packages/django/utils/decorators.py", line 133, in _wrapped_view
    response = view_func(request, *args, **kwargs)
  File "/home/wartinich/.local/lib/python3.10/site-packages/django/contrib/auth/views.py", line 232, in dispatch
    return super().dispatch(*args, **kwargs)
  File "/home/wartinich/.local/lib/python3.10/site-packages/django/views/generic/base.py", line 119, in dispatch
    return handler(request, *args, **kwargs)
  File "/home/wartinich/.local/lib/python3.10/site-packages/django/views/generic/edit.py", line 153, in post
    return self.form_valid(form)
  File "/home/wartinich/.local/lib/python3.10/site-packages/django/contrib/auth/views.py", line 245, in form_valid
    form.save(**opts)
  File "/home/wartinich/.local/lib/python3.10/site-packages/django/contrib/auth/forms.py", line 343, in save
    self.send_mail(
  File "/home/wartinich/.local/lib/python3.10/site-packages/django/contrib/auth/forms.py", line 284, in send_mail
    email_message.send()
  File "/home/wartinich/.local/lib/python3.10/site-packages/django/core/mail/message.py", line 298, in send
    return self.get_connection(fail_silently).send_messages([self])
  File "/home/wartinich/.local/lib/python3.10/site-packages/django/core/mail/backends/smtp.py", line 124, in send_messages
    new_conn_created = self.open()
  File "/home/wartinich/.local/lib/python3.10/site-packages/django/core/mail/backends/smtp.py", line 80, in open
    self.connection = self.connection_class(
  File "/usr/local/lib/python3.10/smtplib.py", line 1050, in __init__
    SMTP.__init__(self, host, port, local_hostname, timeout,
  File "/usr/local/lib/python3.10/smtplib.py", line 255, in __init__
    (code, msg) = self.connect(host, port)
  File "/usr/local/lib/python3.10/smtplib.py", line 341, in connect
    self.sock = self._get_socket(host, port, self.timeout)
  File "/usr/local/lib/python3.10/smtplib.py", line 1057, in _get_socket
    new_socket = self.context.wrap_socket(new_socket,
  File "/usr/local/lib/python3.10/ssl.py", line 512, in wrap_socket
    return self.sslsocket_class._create(
  File "/usr/local/lib/python3.10/ssl.py", line 1070, in _create
    self.do_handshake()
  File "/usr/local/lib/python3.10/ssl.py", line 1341, in do_handshake
    self._sslobj.do_handshake()
ssl.SSLError: [SSL: WRONG_VERSION_NUMBER] wrong version number (_ssl.c:997)
ERROR [2022-06-13 11:09:24,118] - [django.server:log_message:187] "POST /password-reset/ HTTP/1.1" 500 155268
INFO [2022-06-13 11:10:59,275] - [django.utils.autoreload:run_with_reloader:677] Watching for file changes with StatReloader
ERROR [2022-06-13 11:11:05,390] - [django.request:log_response:241] Internal Server Error: /password-reset/
Traceback (most recent call last):
  File "/home/wartinich/.local/lib/python3.10/site-packages/django/core/handlers/exception.py", line 55, in inner
    response = get_response(request)
  File "/home/wartinich/.local/lib/python3.10/site-packages/django/core/handlers/base.py", line 197, in _get_response
    response = wrapped_callback(request, *callback_args, **callback_kwargs)
  File "/home/wartinich/.local/lib/python3.10/site-packages/django/views/generic/base.py", line 84, in view
    return self.dispatch(request, *args, **kwargs)
  File "/home/wartinich/.local/lib/python3.10/site-packages/django/utils/decorators.py", line 46, in _wrapper
    return bound_method(*args, **kwargs)
  File "/home/wartinich/.local/lib/python3.10/site-packages/django/utils/decorators.py", line 133, in _wrapped_view
    response = view_func(request, *args, **kwargs)
  File "/home/wartinich/.local/lib/python3.10/site-packages/django/contrib/auth/views.py", line 232, in dispatch
    return super().dispatch(*args, **kwargs)
  File "/home/wartinich/.local/lib/python3.10/site-packages/django/views/generic/base.py", line 119, in dispatch
    return handler(request, *args, **kwargs)
  File "/home/wartinich/.local/lib/python3.10/site-packages/django/views/generic/edit.py", line 153, in post
    return self.form_valid(form)
  File "/home/wartinich/.local/lib/python3.10/site-packages/django/contrib/auth/views.py", line 245, in form_valid
    form.save(**opts)
  File "/home/wartinich/.local/lib/python3.10/site-packages/django/contrib/auth/forms.py", line 343, in save
    self.send_mail(
  File "/home/wartinich/.local/lib/python3.10/site-packages/django/contrib/auth/forms.py", line 284, in send_mail
    email_message.send()
  File "/home/wartinich/.local/lib/python3.10/site-packages/django/core/mail/message.py", line 298, in send
    return self.get_connection(fail_silently).send_messages([self])
  File "/home/wartinich/.local/lib/python3.10/site-packages/django/core/mail/backends/smtp.py", line 131, in send_messages
    sent = self._send(message)
  File "/home/wartinich/.local/lib/python3.10/site-packages/django/core/mail/backends/smtp.py", line 149, in _send
    self.connection.sendmail(
  File "/usr/local/lib/python3.10/smtplib.py", line 887, in sendmail
    raise SMTPSenderRefused(code, resp, from_addr)
smtplib.SMTPSenderRefused: (530, b'5.7.0 Authentication Required. Learn more at\n5.7.0  https://support.google.com/mail/?p=WantAuthError f13-20020a19380d000000b0047255d21179sm947729lfa.168 - gsmtp', 'webmaster@localhost')
ERROR [2022-06-13 11:11:05,392] - [django.server:log_message:187] "POST /password-reset/ HTTP/1.1" 500 130159
INFO [2022-06-13 11:13:14,507] - [django.utils.autoreload:run_with_reloader:677] Watching for file changes with StatReloader
WARNING [2022-06-13 11:13:17,767] - [django.request:log_response:241] Not Found: /
WARNING [2022-06-13 11:13:17,768] - [django.server:log_message:187] "GET / HTTP/1.1" 404 4211
INFO [2022-06-13 11:13:24,636] - [django.server:log_message:187] "GET /login/ HTTP/1.1" 200 950
INFO [2022-06-13 11:13:41,002] - [django.server:log_message:187] "POST /login/ HTTP/1.1" 200 998
INFO [2022-06-13 11:13:50,807] - [django.server:log_message:187] "GET /password-reset/ HTTP/1.1" 200 787
ERROR [2022-06-13 11:14:04,037] - [django.request:log_response:241] Internal Server Error: /password-reset/
Traceback (most recent call last):
  File "/home/wartinich/.local/lib/python3.10/site-packages/django/core/handlers/exception.py", line 55, in inner
    response = get_response(request)
  File "/home/wartinich/.local/lib/python3.10/site-packages/django/core/handlers/base.py", line 197, in _get_response
    response = wrapped_callback(request, *callback_args, **callback_kwargs)
  File "/home/wartinich/.local/lib/python3.10/site-packages/django/views/generic/base.py", line 84, in view
    return self.dispatch(request, *args, **kwargs)
  File "/home/wartinich/.local/lib/python3.10/site-packages/django/utils/decorators.py", line 46, in _wrapper
    return bound_method(*args, **kwargs)
  File "/home/wartinich/.local/lib/python3.10/site-packages/django/utils/decorators.py", line 133, in _wrapped_view
    response = view_func(request, *args, **kwargs)
  File "/home/wartinich/.local/lib/python3.10/site-packages/django/contrib/auth/views.py", line 232, in dispatch
    return super().dispatch(*args, **kwargs)
  File "/home/wartinich/.local/lib/python3.10/site-packages/django/views/generic/base.py", line 119, in dispatch
    return handler(request, *args, **kwargs)
  File "/home/wartinich/.local/lib/python3.10/site-packages/django/views/generic/edit.py", line 153, in post
    return self.form_valid(form)
  File "/home/wartinich/.local/lib/python3.10/site-packages/django/contrib/auth/views.py", line 245, in form_valid
    form.save(**opts)
  File "/home/wartinich/.local/lib/python3.10/site-packages/django/contrib/auth/forms.py", line 343, in save
    self.send_mail(
  File "/home/wartinich/.local/lib/python3.10/site-packages/django/contrib/auth/forms.py", line 284, in send_mail
    email_message.send()
  File "/home/wartinich/.local/lib/python3.10/site-packages/django/core/mail/message.py", line 298, in send
    return self.get_connection(fail_silently).send_messages([self])
  File "/home/wartinich/.local/lib/python3.10/site-packages/django/core/mail/backends/smtp.py", line 124, in send_messages
    new_conn_created = self.open()
  File "/home/wartinich/.local/lib/python3.10/site-packages/django/core/mail/backends/smtp.py", line 91, in open
    self.connection.login(self.username, self.password)
  File "/usr/local/lib/python3.10/smtplib.py", line 750, in login
    raise last_exception
  File "/usr/local/lib/python3.10/smtplib.py", line 739, in login
    (code, resp) = self.auth(
  File "/usr/local/lib/python3.10/smtplib.py", line 662, in auth
    raise SMTPAuthenticationError(code, resp)
smtplib.SMTPAuthenticationError: (535, b'5.7.8 Username and Password not accepted. Learn more at\n5.7.8  https://support.google.com/mail/?p=BadCredentials c18-20020a056512105200b00478f1bd611csm942514lfb.284 - gsmtp')
ERROR [2022-06-13 11:14:04,039] - [django.server:log_message:187] "POST /password-reset/ HTTP/1.1" 500 139678
INFO [2022-06-13 11:52:36,130] - [django.utils.autoreload:run_with_reloader:677] Watching for file changes with StatReloader
INFO [2022-06-13 11:52:41,924] - [django.server:log_message:187] "GET /login/ HTTP/1.1" 200 667
ERROR [2022-06-13 11:52:43,914] - [django.request:log_response:241] Internal Server Error: /login/
Traceback (most recent call last):
  File "/home/wartinich/.local/lib/python3.10/site-packages/django/core/handlers/exception.py", line 55, in inner
    response = get_response(request)
  File "/home/wartinich/.local/lib/python3.10/site-packages/django/core/handlers/base.py", line 197, in _get_response
    response = wrapped_callback(request, *callback_args, **callback_kwargs)
  File "/home/wartinich/.local/lib/python3.10/site-packages/django/views/generic/base.py", line 84, in view
    return self.dispatch(request, *args, **kwargs)
  File "/home/wartinich/.local/lib/python3.10/site-packages/django/views/generic/base.py", line 119, in dispatch
    return handler(request, *args, **kwargs)
  File "/home/wartinich/Projects/voice_generator/src/users/views.py", line 23, in post
    user = authenticate(
NameError: name 'authenticate' is not defined
ERROR [2022-06-13 11:52:43,915] - [django.server:log_message:187] "POST /login/ HTTP/1.1" 500 75941
INFO [2022-06-13 11:56:00,149] - [django.utils.autoreload:trigger_reload:266] /home/wartinich/Projects/voice_generator/src/users/views.py changed, reloading.
INFO [2022-06-13 11:56:00,937] - [django.utils.autoreload:run_with_reloader:677] Watching for file changes with StatReloader
INFO [2022-06-13 11:56:55,436] - [django.utils.autoreload:trigger_reload:266] /home/wartinich/Projects/voice_generator/src/users/views.py changed, reloading.
INFO [2022-06-13 11:56:56,122] - [django.utils.autoreload:run_with_reloader:677] Watching for file changes with StatReloader
INFO [2022-06-13 11:57:08,153] - [django.server:log_message:187] "POST /login/ HTTP/1.1" 200 816
INFO [2022-06-13 11:57:55,973] - [django.server:log_message:187] "POST /login/ HTTP/1.1" 200 884
INFO [2022-06-13 11:58:23,196] - [django.server:log_message:187] "POST /login/ HTTP/1.1" 200 950
INFO [2022-06-13 11:59:08,199] - [django.utils.autoreload:trigger_reload:266] /home/wartinich/Projects/voice_generator/src/users/views.py changed, reloading.
INFO [2022-06-13 11:59:08,722] - [django.utils.autoreload:run_with_reloader:677] Watching for file changes with StatReloader
INFO [2022-06-13 11:59:15,539] - [django.server:log_message:187] "POST /login/ HTTP/1.1" 200 950
INFO [2022-06-13 12:00:52,155] - [django.utils.autoreload:trigger_reload:266] /home/wartinich/Projects/voice_generator/src/users/views.py changed, reloading.
INFO [2022-06-13 12:00:52,716] - [django.utils.autoreload:run_with_reloader:677] Watching for file changes with StatReloader
INFO [2022-06-13 12:01:15,348] - [django.utils.autoreload:trigger_reload:266] /home/wartinich/Projects/voice_generator/src/users/urls.py changed, reloading.
INFO [2022-06-13 12:01:15,941] - [django.utils.autoreload:run_with_reloader:677] Watching for file changes with StatReloader
ERROR [2022-06-13 12:01:18,386] - [django.request:log_response:241] Internal Server Error: /login/
Traceback (most recent call last):
  File "/home/wartinich/.local/lib/python3.10/site-packages/django/core/handlers/exception.py", line 55, in inner
    response = get_response(request)
  File "/home/wartinich/.local/lib/python3.10/site-packages/django/core/handlers/base.py", line 197, in _get_response
    response = wrapped_callback(request, *callback_args, **callback_kwargs)
  File "/home/wartinich/Projects/voice_generator/src/users/views.py", line 30, in user_login
    return render(request, 'account/login.html', {'form': form})
  File "/home/wartinich/.local/lib/python3.10/site-packages/django/shortcuts.py", line 24, in render
    content = loader.render_to_string(template_name, context, request, using=using)
  File "/home/wartinich/.local/lib/python3.10/site-packages/django/template/loader.py", line 61, in render_to_string
    template = get_template(template_name, using=using)
  File "/home/wartinich/.local/lib/python3.10/site-packages/django/template/loader.py", line 19, in get_template
    raise TemplateDoesNotExist(template_name, chain=chain)
django.template.exceptions.TemplateDoesNotExist: account/login.html
ERROR [2022-06-13 12:01:18,387] - [django.server:log_message:187] "POST /login/ HTTP/1.1" 500 82580
INFO [2022-06-13 12:01:33,637] - [django.utils.autoreload:trigger_reload:266] /home/wartinich/Projects/voice_generator/src/users/views.py changed, reloading.
INFO [2022-06-13 12:01:34,234] - [django.utils.autoreload:run_with_reloader:677] Watching for file changes with StatReloader
INFO [2022-06-13 12:01:36,061] - [django.server:log_message:187] "POST /login/ HTTP/1.1" 200 950
INFO [2022-06-13 12:01:37,603] - [django.server:log_message:187] "POST /login/ HTTP/1.1" 200 950
INFO [2022-06-13 12:01:38,879] - [django.server:log_message:187] "POST /login/ HTTP/1.1" 200 950
INFO [2022-06-13 12:01:39,425] - [django.server:log_message:187] "POST /login/ HTTP/1.1" 200 950
INFO [2022-06-13 12:01:39,808] - [django.server:log_message:187] "POST /login/ HTTP/1.1" 200 950
INFO [2022-06-13 12:01:40,204] - [django.server:log_message:187] "POST /login/ HTTP/1.1" 200 950
INFO [2022-06-13 12:01:40,618] - [django.server:log_message:187] "POST /login/ HTTP/1.1" 200 950
INFO [2022-06-13 12:01:40,991] - [django.server:log_message:187] "POST /login/ HTTP/1.1" 200 950
INFO [2022-06-13 12:01:41,194] - [django.server:log_message:187] "POST /login/ HTTP/1.1" 200 950
INFO [2022-06-13 12:01:41,568] - [django.server:log_message:187] "POST /login/ HTTP/1.1" 200 950
INFO [2022-06-13 12:01:41,943] - [django.server:log_message:187] "POST /login/ HTTP/1.1" 200 950
INFO [2022-06-13 12:01:42,322] - [django.server:log_message:187] "POST /login/ HTTP/1.1" 200 950
INFO [2022-06-13 12:01:42,692] - [django.server:log_message:187] "POST /login/ HTTP/1.1" 200 950
INFO [2022-06-13 12:01:43,072] - [django.server:log_message:187] "POST /login/ HTTP/1.1" 200 950
INFO [2022-06-13 12:01:43,458] - [django.server:log_message:187] "POST /login/ HTTP/1.1" 200 950
INFO [2022-06-13 12:01:43,812] - [django.server:log_message:187] "POST /login/ HTTP/1.1" 200 950
INFO [2022-06-13 12:01:44,181] - [django.server:log_message:187] "POST /login/ HTTP/1.1" 200 950
INFO [2022-06-13 12:01:44,542] - [django.server:log_message:187] "POST /login/ HTTP/1.1" 200 950
INFO [2022-06-13 12:01:44,911] - [django.server:log_message:187] "POST /login/ HTTP/1.1" 200 950
INFO [2022-06-13 12:01:45,293] - [django.server:log_message:187] "POST /login/ HTTP/1.1" 200 950
INFO [2022-06-13 12:01:45,653] - [django.server:log_message:187] "POST /login/ HTTP/1.1" 200 950
INFO [2022-06-13 12:01:46,005] - [django.server:log_message:187] "POST /login/ HTTP/1.1" 200 950
INFO [2022-06-13 12:01:46,349] - [django.server:log_message:187] "POST /login/ HTTP/1.1" 200 950
INFO [2022-06-13 12:02:16,622] - [django.utils.autoreload:trigger_reload:266] /home/wartinich/Projects/voice_generator/src/users/views.py changed, reloading.
INFO [2022-06-13 12:02:17,252] - [django.utils.autoreload:run_with_reloader:677] Watching for file changes with StatReloader
INFO [2022-06-13 12:02:19,696] - [django.server:log_message:187] "POST /login/ HTTP/1.1" 200 950
INFO [2022-06-13 12:02:21,437] - [django.server:log_message:187] "POST /login/ HTTP/1.1" 200 950
INFO [2022-06-13 12:02:21,965] - [django.server:log_message:187] "POST /login/ HTTP/1.1" 200 950
INFO [2022-06-13 12:02:22,318] - [django.server:log_message:187] "POST /login/ HTTP/1.1" 200 950
INFO [2022-06-13 12:02:22,664] - [django.server:log_message:187] "POST /login/ HTTP/1.1" 200 950
INFO [2022-06-13 12:02:23,044] - [django.server:log_message:187] "POST /login/ HTTP/1.1" 200 950
INFO [2022-06-13 12:02:23,385] - [django.server:log_message:187] "POST /login/ HTTP/1.1" 200 950
INFO [2022-06-13 12:02:23,741] - [django.server:log_message:187] "POST /login/ HTTP/1.1" 200 950
INFO [2022-06-13 12:02:24,084] - [django.server:log_message:187] "POST /login/ HTTP/1.1" 200 950
INFO [2022-06-13 12:02:24,615] - [django.server:log_message:187] "POST /login/ HTTP/1.1" 200 950
INFO [2022-06-13 12:02:24,920] - [django.server:log_message:187] "POST /login/ HTTP/1.1" 200 950
INFO [2022-06-13 12:02:46,009] - [django.server:log_message:187] "POST /login/ HTTP/1.1" 200 950
INFO [2022-06-13 12:02:47,788] - [django.server:log_message:187] "POST /login/ HTTP/1.1" 200 950
INFO [2022-06-13 12:02:48,720] - [django.server:log_message:187] "POST /login/ HTTP/1.1" 200 950
INFO [2022-06-13 12:02:49,289] - [django.server:log_message:187] "POST /login/ HTTP/1.1" 200 950
INFO [2022-06-13 12:02:49,664] - [django.server:log_message:187] "POST /login/ HTTP/1.1" 200 950
INFO [2022-06-13 12:02:50,048] - [django.server:log_message:187] "POST /login/ HTTP/1.1" 200 950
INFO [2022-06-13 12:02:50,418] - [django.server:log_message:187] "POST /login/ HTTP/1.1" 200 950
INFO [2022-06-13 12:02:50,801] - [django.server:log_message:187] "POST /login/ HTTP/1.1" 200 950
INFO [2022-06-13 12:02:51,189] - [django.server:log_message:187] "POST /login/ HTTP/1.1" 200 950
INFO [2022-06-13 12:02:51,573] - [django.server:log_message:187] "POST /login/ HTTP/1.1" 200 950
INFO [2022-06-13 12:02:51,951] - [django.server:log_message:187] "POST /login/ HTTP/1.1" 200 950
INFO [2022-06-13 12:02:52,329] - [django.server:log_message:187] "POST /login/ HTTP/1.1" 200 950
INFO [2022-06-13 12:04:41,784] - [django.utils.autoreload:trigger_reload:266] /home/wartinich/Projects/voice_generator/src/users/urls.py changed, reloading.
INFO [2022-06-13 12:04:42,385] - [django.utils.autoreload:run_with_reloader:677] Watching for file changes with StatReloader
INFO [2022-06-13 12:04:43,626] - [django.utils.autoreload:trigger_reload:266] /home/wartinich/Projects/voice_generator/src/users/views.py changed, reloading.
INFO [2022-06-13 12:04:44,250] - [django.utils.autoreload:run_with_reloader:677] Watching for file changes with StatReloader
INFO [2022-06-13 12:04:59,482] - [django.server:log_message:187] "POST /login/ HTTP/1.1" 200 950
INFO [2022-06-13 12:05:01,019] - [django.server:log_message:187] "POST /login/ HTTP/1.1" 200 950
INFO [2022-06-13 12:05:01,653] - [django.server:log_message:187] "POST /login/ HTTP/1.1" 200 950
INFO [2022-06-13 12:05:02,197] - [django.server:log_message:187] "POST /login/ HTTP/1.1" 200 950
INFO [2022-06-13 12:05:02,984] - [django.server:log_message:187] "POST /login/ HTTP/1.1" 200 950
INFO [2022-06-13 12:05:15,508] - [django.utils.autoreload:trigger_reload:266] /home/wartinich/Projects/voice_generator/src/users/views.py changed, reloading.
INFO [2022-06-13 12:05:16,336] - [django.utils.autoreload:run_with_reloader:677] Watching for file changes with StatReloader
INFO [2022-06-13 12:05:17,514] - [django.server:log_message:187] "POST /login/ HTTP/1.1" 200 950
INFO [2022-06-13 12:05:18,696] - [django.server:log_message:187] "POST /login/ HTTP/1.1" 200 950
INFO [2022-06-13 12:05:19,295] - [django.server:log_message:187] "POST /login/ HTTP/1.1" 200 950
INFO [2022-06-13 12:05:19,461] - [django.server:log_message:187] "POST /login/ HTTP/1.1" 200 950
INFO [2022-06-13 12:05:19,643] - [django.server:log_message:187] "POST /login/ HTTP/1.1" 200 950
INFO [2022-06-13 12:05:19,845] - [django.server:log_message:187] "POST /login/ HTTP/1.1" 200 950
INFO [2022-06-13 12:05:20,075] - [django.server:log_message:187] "POST /login/ HTTP/1.1" 200 950
INFO [2022-06-13 12:05:20,294] - [django.server:log_message:187] "POST /login/ HTTP/1.1" 200 950
INFO [2022-06-13 12:05:32,027] - [django.utils.autoreload:trigger_reload:266] /home/wartinich/Projects/voice_generator/src/users/views.py changed, reloading.
INFO [2022-06-13 12:05:32,520] - [django.utils.autoreload:run_with_reloader:677] Watching for file changes with StatReloader
INFO [2022-06-13 12:05:33,738] - [django.server:log_message:187] "POST /login/ HTTP/1.1" 200 950
INFO [2022-06-13 12:05:34,432] - [django.server:log_message:187] "POST /login/ HTTP/1.1" 200 950
INFO [2022-06-13 12:05:35,089] - [django.server:log_message:187] "POST /login/ HTTP/1.1" 200 950
INFO [2022-06-13 12:05:35,554] - [django.server:log_message:187] "POST /login/ HTTP/1.1" 200 950
INFO [2022-06-13 12:05:35,755] - [django.server:log_message:187] "POST /login/ HTTP/1.1" 200 950
INFO [2022-06-13 12:05:36,114] - [django.server:log_message:187] "POST /login/ HTTP/1.1" 200 950
INFO [2022-06-13 12:05:36,462] - [django.server:log_message:187] "POST /login/ HTTP/1.1" 200 950
INFO [2022-06-13 12:05:36,807] - [django.server:log_message:187] "POST /login/ HTTP/1.1" 200 950
INFO [2022-06-13 12:05:39,661] - [django.server:log_message:187] "POST /login/ HTTP/1.1" 200 950
INFO [2022-06-13 12:06:05,376] - [django.server:log_message:187] "POST /login/ HTTP/1.1" 200 935
INFO [2022-06-13 12:06:06,377] - [django.server:log_message:187] "POST /login/ HTTP/1.1" 200 935
INFO [2022-06-13 12:06:06,982] - [django.server:log_message:187] "POST /login/ HTTP/1.1" 200 935
INFO [2022-06-13 12:06:07,233] - [django.server:log_message:187] "POST /login/ HTTP/1.1" 200 935
INFO [2022-06-13 12:06:35,270] - [django.server:log_message:187] "POST /login/ HTTP/1.1" 200 935
INFO [2022-06-13 12:06:35,689] - [django.server:log_message:187] "POST /login/ HTTP/1.1" 200 935
INFO [2022-06-13 12:06:35,899] - [django.server:log_message:187] "POST /login/ HTTP/1.1" 200 935
INFO [2022-06-13 12:06:36,120] - [django.server:log_message:187] "POST /login/ HTTP/1.1" 200 935
INFO [2022-06-13 12:06:36,777] - [django.server:log_message:187] "POST /login/ HTTP/1.1" 200 935
INFO [2022-06-13 12:06:37,461] - [django.server:log_message:187] "POST /login/ HTTP/1.1" 200 935
INFO [2022-06-13 12:06:51,857] - [django.server:log_message:187] "GET /logout/ HTTP/1.1" 200 643
INFO [2022-06-13 12:06:53,632] - [django.server:log_message:187] "POST /logout/ HTTP/1.1" 200 643
INFO [2022-06-13 12:06:54,331] - [django.server:log_message:187] "POST /logout/ HTTP/1.1" 200 643
INFO [2022-06-13 12:07:02,783] - [django.server:log_message:187] "GET /login/ HTTP/1.1" 200 869
ERROR [2022-06-13 12:07:25,925] - [django.request:log_response:241] Internal Server Error: /login/
Traceback (most recent call last):
  File "/home/wartinich/.local/lib/python3.10/site-packages/django/core/handlers/exception.py", line 55, in inner
    response = get_response(request)
  File "/home/wartinich/.local/lib/python3.10/site-packages/django/core/handlers/base.py", line 197, in _get_response
    response = wrapped_callback(request, *callback_args, **callback_kwargs)
  File "/home/wartinich/.local/lib/python3.10/site-packages/django/views/generic/base.py", line 84, in view
    return self.dispatch(request, *args, **kwargs)
  File "/home/wartinich/.local/lib/python3.10/site-packages/django/views/generic/base.py", line 119, in dispatch
    return handler(request, *args, **kwargs)
  File "/home/wartinich/Projects/voice_generator/src/users/views.py", line 29, in post
    user = authenticate(
NameError: name 'authenticate' is not defined
ERROR [2022-06-13 12:07:25,927] - [django.server:log_message:187] "POST /login/ HTTP/1.1" 500 76434
INFO [2022-06-13 12:10:14,601] - [django.utils.autoreload:trigger_reload:266] /home/wartinich/Projects/voice_generator/src/users/views.py changed, reloading.
INFO [2022-06-13 12:10:15,091] - [django.utils.autoreload:run_with_reloader:677] Watching for file changes with StatReloader
INFO [2022-06-13 12:10:38,553] - [django.server:log_message:187] "POST /login/ HTTP/1.1" 200 932
INFO [2022-06-13 12:10:40,023] - [django.server:log_message:187] "POST /login/ HTTP/1.1" 200 932
INFO [2022-06-13 12:10:40,813] - [django.server:log_message:187] "POST /login/ HTTP/1.1" 200 932
INFO [2022-06-13 12:10:42,086] - [django.server:log_message:187] "POST /login/ HTTP/1.1" 200 932
INFO [2022-06-13 12:10:43,034] - [django.server:log_message:187] "POST /login/ HTTP/1.1" 200 932
INFO [2022-06-13 12:10:43,895] - [django.server:log_message:187] "POST /login/ HTTP/1.1" 200 932
INFO [2022-06-13 12:10:44,414] - [django.server:log_message:187] "POST /login/ HTTP/1.1" 200 932
INFO [2022-06-13 12:10:44,784] - [django.server:log_message:187] "POST /login/ HTTP/1.1" 200 932
INFO [2022-06-13 12:10:45,302] - [django.server:log_message:187] "POST /login/ HTTP/1.1" 200 932
INFO [2022-06-13 12:11:06,750] - [django.utils.autoreload:trigger_reload:266] /home/wartinich/Projects/voice_generator/src/users/views.py changed, reloading.
INFO [2022-06-13 12:11:07,229] - [django.utils.autoreload:run_with_reloader:677] Watching for file changes with StatReloader
INFO [2022-06-13 12:12:23,164] - [django.utils.autoreload:trigger_reload:266] /home/wartinich/Projects/voice_generator/src/users/views.py changed, reloading.
INFO [2022-06-13 12:12:23,797] - [django.utils.autoreload:run_with_reloader:677] Watching for file changes with StatReloader
INFO [2022-06-13 12:12:54,713] - [django.utils.autoreload:trigger_reload:266] /home/wartinich/Projects/voice_generator/src/users/views.py changed, reloading.
INFO [2022-06-13 12:12:55,154] - [django.utils.autoreload:run_with_reloader:677] Watching for file changes with StatReloader
INFO [2022-06-13 12:13:04,609] - [django.utils.autoreload:trigger_reload:266] /home/wartinich/Projects/voice_generator/src/users/views.py changed, reloading.
INFO [2022-06-13 12:13:05,145] - [django.utils.autoreload:run_with_reloader:677] Watching for file changes with StatReloader
INFO [2022-06-13 12:13:20,578] - [django.utils.autoreload:trigger_reload:266] /home/wartinich/Projects/voice_generator/src/users/views.py changed, reloading.
INFO [2022-06-13 12:13:21,104] - [django.utils.autoreload:run_with_reloader:677] Watching for file changes with StatReloader
INFO [2022-06-13 12:13:31,306] - [django.server:log_message:187] "POST /login/ HTTP/1.1" 200 932
INFO [2022-06-13 12:13:32,122] - [django.server:log_message:187] "POST /login/ HTTP/1.1" 200 932
INFO [2022-06-13 12:13:32,507] - [django.server:log_message:187] "POST /login/ HTTP/1.1" 200 932
INFO [2022-06-13 12:13:33,094] - [django.server:log_message:187] "POST /login/ HTTP/1.1" 200 932
INFO [2022-06-13 12:13:33,466] - [django.server:log_message:187] "POST /login/ HTTP/1.1" 200 932
INFO [2022-06-13 12:13:33,838] - [django.server:log_message:187] "POST /login/ HTTP/1.1" 200 932
INFO [2022-06-13 12:13:34,001] - [django.server:log_message:187] "POST /login/ HTTP/1.1" 200 932
INFO [2022-06-13 12:13:34,379] - [django.server:log_message:187] "POST /login/ HTTP/1.1" 200 932
INFO [2022-06-13 12:13:36,158] - [django.server:log_message:187] "POST /login/ HTTP/1.1" 200 932
INFO [2022-06-13 12:14:07,344] - [django.server:log_message:187] "POST /login/ HTTP/1.1" 200 935
INFO [2022-06-13 12:14:28,477] - [django.server:log_message:187] "POST /login/ HTTP/1.1" 200 935
INFO [2022-06-13 12:14:28,831] - [django.server:log_message:187] "POST /login/ HTTP/1.1" 200 935
INFO [2022-06-13 12:14:29,171] - [django.server:log_message:187] "POST /login/ HTTP/1.1" 200 935
INFO [2022-06-13 12:14:29,519] - [django.server:log_message:187] "POST /login/ HTTP/1.1" 200 935
INFO [2022-06-13 12:14:30,168] - [django.server:log_message:187] "POST /login/ HTTP/1.1" 200 935
INFO [2022-06-13 12:14:30,481] - [django.server:log_message:187] "POST /login/ HTTP/1.1" 200 935
INFO [2022-06-13 12:14:54,183] - [django.utils.autoreload:trigger_reload:266] /home/wartinich/Projects/voice_generator/src/users/views.py changed, reloading.
INFO [2022-06-13 12:14:54,743] - [django.utils.autoreload:run_with_reloader:677] Watching for file changes with StatReloader
INFO [2022-06-13 12:14:55,768] - [django.server:log_message:187] "POST /login/ HTTP/1.1" 200 935
INFO [2022-06-13 12:15:25,696] - [django.utils.autoreload:trigger_reload:266] /home/wartinich/Projects/voice_generator/src/users/views.py changed, reloading.
INFO [2022-06-13 12:15:26,279] - [django.utils.autoreload:run_with_reloader:677] Watching for file changes with StatReloader
INFO [2022-06-13 12:15:27,710] - [django.server:log_message:187] "POST /login/ HTTP/1.1" 200 12
INFO [2022-06-13 12:15:58,254] - [django.utils.autoreload:trigger_reload:266] /home/wartinich/Projects/voice_generator/src/users/views.py changed, reloading.
INFO [2022-06-13 12:15:59,007] - [django.utils.autoreload:run_with_reloader:677] Watching for file changes with StatReloader
INFO [2022-06-13 12:16:00,339] - [django.server:log_message:187] "POST /login/ HTTP/1.1" 200 12
INFO [2022-06-13 12:17:56,627] - [django.utils.autoreload:trigger_reload:266] /home/wartinich/Projects/voice_generator/src/users/views.py changed, reloading.
INFO [2022-06-13 12:17:57,162] - [django.utils.autoreload:run_with_reloader:677] Watching for file changes with StatReloader
INFO [2022-06-13 12:18:00,300] - [django.server:log_message:187] "POST /login/ HTTP/1.1" 200 12
INFO [2022-06-13 12:18:03,492] - [django.server:log_message:187] "POST /login/ HTTP/1.1" 200 12
INFO [2022-06-13 12:18:07,324] - [django.server:log_message:187] "POST /login/ HTTP/1.1" 200 12
INFO [2022-06-13 12:19:48,299] - [django.server:log_message:187] "POST /login/ HTTP/1.1" 200 12
INFO [2022-06-13 12:19:51,378] - [django.server:log_message:187] "POST /login/ HTTP/1.1" 200 12
INFO [2022-06-13 12:20:03,056] - [django.server:log_message:187] "POST /login/ HTTP/1.1" 200 12
INFO [2022-06-13 12:20:05,539] - [django.server:log_message:187] "POST /login/ HTTP/1.1" 200 12
INFO [2022-06-13 12:20:33,606] - [django.utils.autoreload:trigger_reload:266] /home/wartinich/Projects/voice_generator/src/users/views.py changed, reloading.
INFO [2022-06-13 12:20:34,250] - [django.utils.autoreload:run_with_reloader:677] Watching for file changes with StatReloader
INFO [2022-06-13 12:21:00,089] - [django.server:log_message:187] "POST /login/ HTTP/1.1" 200 12
INFO [2022-06-13 12:21:03,377] - [django.server:log_message:187] "POST /login/ HTTP/1.1" 200 12
INFO [2022-06-13 12:26:40,490] - [django.utils.autoreload:run_with_reloader:677] Watching for file changes with StatReloader
INFO [2022-06-14 05:52:36,454] - [django.utils.autoreload:run_with_reloader:677] Watching for file changes with StatReloader
INFO [2022-06-14 05:52:42,528] - [django.server:log_message:187] "GET /admin/ HTTP/1.1" 302 0
INFO [2022-06-14 05:52:42,564] - [django.server:log_message:187] "GET /admin/login/?next=/admin/ HTTP/1.1" 200 2215
INFO [2022-06-14 05:52:42,599] - [django.server:log_message:187] "GET /static/admin/css/base.css HTTP/1.1" 304 0
INFO [2022-06-14 05:52:42,604] - [django.server:log_message:187] "GET /static/admin/js/nav_sidebar.js HTTP/1.1" 304 0
INFO [2022-06-14 05:52:42,605] - [django.server:log_message:187] "GET /static/admin/css/nav_sidebar.css HTTP/1.1" 304 0
INFO [2022-06-14 05:52:42,609] - [django.server:log_message:187] "GET /static/admin/css/login.css HTTP/1.1" 304 0
INFO [2022-06-14 05:52:42,613] - [django.server:log_message:187] "GET /static/admin/css/responsive.css HTTP/1.1" 304 0
INFO [2022-06-14 05:52:43,902] - [django.server:log_message:187] "GET /admin/ HTTP/1.1" 302 0
INFO [2022-06-14 05:52:43,926] - [django.server:log_message:187] "GET /admin/login/?next=/admin/ HTTP/1.1" 200 2215
INFO [2022-06-14 05:52:43,970] - [django.server:log_message:187] "GET /static/admin/css/fonts.css HTTP/1.1" 304 0
INFO [2022-06-14 05:52:44,022] - [django.server:log_message:187] "GET /static/admin/fonts/Roboto-Regular-webfont.woff HTTP/1.1" 304 0
INFO [2022-06-14 05:52:44,023] - [django.server:log_message:187] "GET /static/admin/fonts/Roboto-Light-webfont.woff HTTP/1.1" 304 0
INFO [2022-06-14 05:52:45,595] - [django.server:log_message:187] "POST /admin/login/?next=/admin/ HTTP/1.1" 302 0
INFO [2022-06-14 05:52:45,620] - [django.server:log_message:187] "GET /admin/ HTTP/1.1" 200 3554
INFO [2022-06-14 05:52:45,633] - [django.server:log_message:187] "GET /static/admin/css/dashboard.css HTTP/1.1" 304 0
INFO [2022-06-14 05:52:45,661] - [django.server:log_message:187] "GET /static/admin/img/icon-addlink.svg HTTP/1.1" 304 0
INFO [2022-06-14 05:52:45,664] - [django.server:log_message:187] "GET /static/admin/img/icon-changelink.svg HTTP/1.1" 304 0
INFO [2022-06-14 05:52:45,694] - [django.server:log_message:187] "GET /static/admin/fonts/Roboto-Bold-webfont.woff HTTP/1.1" 304 0
INFO [2022-06-14 05:52:47,274] - [django.server:log_message:187] "GET /admin/users/user/ HTTP/1.1" 200 6924
INFO [2022-06-14 05:52:47,337] - [django.server:log_message:187] "GET /static/admin/js/admin/RelatedObjectLookups.js HTTP/1.1" 200 5984
INFO [2022-06-14 05:52:47,339] - [django.server:log_message:187] "GET /static/admin/css/changelists.css HTTP/1.1" 200 6932
INFO [2022-06-14 05:52:47,343] - [django.server:log_message:187] "GET /admin/jsi18n/ HTTP/1.1" 200 3343
INFO [2022-06-14 05:52:47,343] - [django.server:log_message:187] "GET /static/admin/js/core.js HTTP/1.1" 200 5698
INFO [2022-06-14 05:52:47,351] - [django.server:log_message:187] "GET /static/admin/js/jquery.init.js HTTP/1.1" 200 347
INFO [2022-06-14 05:52:47,351] - [django.server:log_message:187] "GET /static/admin/js/urlify.js HTTP/1.1" 200 7902
INFO [2022-06-14 05:52:47,353] - [django.server:log_message:187] "GET /static/admin/js/actions.js HTTP/1.1" 200 7872
INFO [2022-06-14 05:52:47,355] - [django.server:log_message:187] "GET /static/admin/js/prepopulate.js HTTP/1.1" 200 1531
INFO [2022-06-14 05:52:47,365] - [django.server:log_message:187] "GET /static/admin/js/vendor/xregexp/xregexp.js HTTP/1.1" 200 232381
INFO [2022-06-14 05:52:47,366] - [django.server:log_message:187] "GET /static/admin/js/vendor/jquery/jquery.js HTTP/1.1" 200 288580
INFO [2022-06-14 05:52:47,411] - [django.server:log_message:187] "GET /static/admin/img/search.svg HTTP/1.1" 200 458
INFO [2022-06-14 05:52:47,446] - [django.server:log_message:187] "GET /static/admin/img/tooltag-add.svg HTTP/1.1" 200 331
INFO [2022-06-14 05:53:24,784] - [django.utils.autoreload:trigger_reload:266] /home/wartinich/Projects/voice_generator/src/users/admin.py changed, reloading.
INFO [2022-06-14 05:53:25,373] - [django.utils.autoreload:run_with_reloader:677] Watching for file changes with StatReloader
INFO [2022-06-14 05:53:26,792] - [django.server:log_message:187] "GET /admin/users/user/ HTTP/1.1" 200 7808
INFO [2022-06-14 05:53:26,817] - [django.server:log_message:187] "GET /admin/jsi18n/ HTTP/1.1" 200 3343
INFO [2022-06-14 05:53:26,853] - [django.server:log_message:187] "GET /static/admin/img/sorting-icons.svg HTTP/1.1" 200 1097
ERROR [2022-06-14 05:53:29,195] - [django.request:log_response:241] Internal Server Error: /admin/users/user/2/change/
Traceback (most recent call last):
  File "/home/wartinich/.local/lib/python3.10/site-packages/django/contrib/admin/options.py", line 804, in get_form
    return modelform_factory(self.model, **defaults)
  File "/home/wartinich/.local/lib/python3.10/site-packages/django/forms/models.py", line 648, in modelform_factory
    return type(form)(class_name, (form,), form_class_attrs)
  File "/home/wartinich/.local/lib/python3.10/site-packages/django/forms/models.py", line 327, in __new__
    raise FieldError(message)
django.core.exceptions.FieldError: Unknown field(s) (is_stuff, show_avatar) specified for User

During handling of the above exception, another exception occurred:

Traceback (most recent call last):
  File "/home/wartinich/.local/lib/python3.10/site-packages/django/core/handlers/exception.py", line 55, in inner
    response = get_response(request)
  File "/home/wartinich/.local/lib/python3.10/site-packages/django/core/handlers/base.py", line 197, in _get_response
    response = wrapped_callback(request, *callback_args, **callback_kwargs)
  File "/home/wartinich/.local/lib/python3.10/site-packages/django/contrib/admin/options.py", line 683, in wrapper
    return self.admin_site.admin_view(view)(*args, **kwargs)
  File "/home/wartinich/.local/lib/python3.10/site-packages/django/utils/decorators.py", line 133, in _wrapped_view
    response = view_func(request, *args, **kwargs)
  File "/home/wartinich/.local/lib/python3.10/site-packages/django/views/decorators/cache.py", line 62, in _wrapped_view_func
    response = view_func(request, *args, **kwargs)
  File "/home/wartinich/.local/lib/python3.10/site-packages/django/contrib/admin/sites.py", line 242, in inner
    return view(request, *args, **kwargs)
  File "/home/wartinich/.local/lib/python3.10/site-packages/django/contrib/admin/options.py", line 1888, in change_view
    return self.changeform_view(request, object_id, form_url, extra_context)
  File "/home/wartinich/.local/lib/python3.10/site-packages/django/utils/decorators.py", line 46, in _wrapper
    return bound_method(*args, **kwargs)
  File "/home/wartinich/.local/lib/python3.10/site-packages/django/utils/decorators.py", line 133, in _wrapped_view
    response = view_func(request, *args, **kwargs)
  File "/home/wartinich/.local/lib/python3.10/site-packages/django/contrib/admin/options.py", line 1745, in changeform_view
    return self._changeform_view(request, object_id, form_url, extra_context)
  File "/home/wartinich/.local/lib/python3.10/site-packages/django/contrib/admin/options.py", line 1781, in _changeform_view
    ModelForm = self.get_form(
  File "/home/wartinich/.local/lib/python3.10/site-packages/django/contrib/auth/admin.py", line 98, in get_form
    return super().get_form(request, obj, **defaults)
  File "/home/wartinich/.local/lib/python3.10/site-packages/django/contrib/admin/options.py", line 806, in get_form
    raise FieldError(
django.core.exceptions.FieldError: Unknown field(s) (is_stuff, show_avatar) specified for User. Check fields/fieldsets/exclude attributes of class UserAdmin.
ERROR [2022-06-14 05:53:29,197] - [django.server:log_message:187] "GET /admin/users/user/2/change/ HTTP/1.1" 500 140235
INFO [2022-06-14 05:54:08,654] - [django.utils.autoreload:trigger_reload:266] /home/wartinich/Projects/voice_generator/src/users/admin.py changed, reloading.
INFO [2022-06-14 05:54:09,115] - [django.utils.autoreload:run_with_reloader:677] Watching for file changes with StatReloader
ERROR [2022-06-14 05:54:14,221] - [django.request:log_response:241] Internal Server Error: /admin/users/user/2/change/
Traceback (most recent call last):
  File "/home/wartinich/.local/lib/python3.10/site-packages/django/contrib/admin/options.py", line 804, in get_form
    return modelform_factory(self.model, **defaults)
  File "/home/wartinich/.local/lib/python3.10/site-packages/django/forms/models.py", line 648, in modelform_factory
    return type(form)(class_name, (form,), form_class_attrs)
  File "/home/wartinich/.local/lib/python3.10/site-packages/django/forms/models.py", line 327, in __new__
    raise FieldError(message)
django.core.exceptions.FieldError: Unknown field(s) (show_avatar) specified for User

During handling of the above exception, another exception occurred:

Traceback (most recent call last):
  File "/home/wartinich/.local/lib/python3.10/site-packages/django/core/handlers/exception.py", line 55, in inner
    response = get_response(request)
  File "/home/wartinich/.local/lib/python3.10/site-packages/django/core/handlers/base.py", line 197, in _get_response
    response = wrapped_callback(request, *callback_args, **callback_kwargs)
  File "/home/wartinich/.local/lib/python3.10/site-packages/django/contrib/admin/options.py", line 683, in wrapper
    return self.admin_site.admin_view(view)(*args, **kwargs)
  File "/home/wartinich/.local/lib/python3.10/site-packages/django/utils/decorators.py", line 133, in _wrapped_view
    response = view_func(request, *args, **kwargs)
  File "/home/wartinich/.local/lib/python3.10/site-packages/django/views/decorators/cache.py", line 62, in _wrapped_view_func
    response = view_func(request, *args, **kwargs)
  File "/home/wartinich/.local/lib/python3.10/site-packages/django/contrib/admin/sites.py", line 242, in inner
    return view(request, *args, **kwargs)
  File "/home/wartinich/.local/lib/python3.10/site-packages/django/contrib/admin/options.py", line 1888, in change_view
    return self.changeform_view(request, object_id, form_url, extra_context)
  File "/home/wartinich/.local/lib/python3.10/site-packages/django/utils/decorators.py", line 46, in _wrapper
    return bound_method(*args, **kwargs)
  File "/home/wartinich/.local/lib/python3.10/site-packages/django/utils/decorators.py", line 133, in _wrapped_view
    response = view_func(request, *args, **kwargs)
  File "/home/wartinich/.local/lib/python3.10/site-packages/django/contrib/admin/options.py", line 1745, in changeform_view
    return self._changeform_view(request, object_id, form_url, extra_context)
  File "/home/wartinich/.local/lib/python3.10/site-packages/django/contrib/admin/options.py", line 1781, in _changeform_view
    ModelForm = self.get_form(
  File "/home/wartinich/.local/lib/python3.10/site-packages/django/contrib/auth/admin.py", line 98, in get_form
    return super().get_form(request, obj, **defaults)
  File "/home/wartinich/.local/lib/python3.10/site-packages/django/contrib/admin/options.py", line 806, in get_form
    raise FieldError(
django.core.exceptions.FieldError: Unknown field(s) (show_avatar) specified for User. Check fields/fieldsets/exclude attributes of class UserAdmin.
ERROR [2022-06-14 05:54:14,223] - [django.server:log_message:187] "GET /admin/users/user/2/change/ HTTP/1.1" 500 140319
INFO [2022-06-14 05:56:10,845] - [django.utils.autoreload:trigger_reload:266] /home/wartinich/Projects/voice_generator/src/users/admin.py changed, reloading.
INFO [2022-06-14 05:56:11,463] - [django.utils.autoreload:run_with_reloader:677] Watching for file changes with StatReloader
ERROR [2022-06-14 05:56:13,570] - [django.request:log_response:241] Internal Server Error: /admin/users/user/2/change/
Traceback (most recent call last):
  File "/home/wartinich/.local/lib/python3.10/site-packages/django/contrib/admin/options.py", line 804, in get_form
    return modelform_factory(self.model, **defaults)
  File "/home/wartinich/.local/lib/python3.10/site-packages/django/forms/models.py", line 648, in modelform_factory
    return type(form)(class_name, (form,), form_class_attrs)
  File "/home/wartinich/.local/lib/python3.10/site-packages/django/forms/models.py", line 327, in __new__
    raise FieldError(message)
django.core.exceptions.FieldError: Unknown field(s) (show_avatar) specified for User

During handling of the above exception, another exception occurred:

Traceback (most recent call last):
  File "/home/wartinich/.local/lib/python3.10/site-packages/django/core/handlers/exception.py", line 55, in inner
    response = get_response(request)
  File "/home/wartinich/.local/lib/python3.10/site-packages/django/core/handlers/base.py", line 197, in _get_response
    response = wrapped_callback(request, *callback_args, **callback_kwargs)
  File "/home/wartinich/.local/lib/python3.10/site-packages/django/contrib/admin/options.py", line 683, in wrapper
    return self.admin_site.admin_view(view)(*args, **kwargs)
  File "/home/wartinich/.local/lib/python3.10/site-packages/django/utils/decorators.py", line 133, in _wrapped_view
    response = view_func(request, *args, **kwargs)
  File "/home/wartinich/.local/lib/python3.10/site-packages/django/views/decorators/cache.py", line 62, in _wrapped_view_func
    response = view_func(request, *args, **kwargs)
  File "/home/wartinich/.local/lib/python3.10/site-packages/django/contrib/admin/sites.py", line 242, in inner
    return view(request, *args, **kwargs)
  File "/home/wartinich/.local/lib/python3.10/site-packages/django/contrib/admin/options.py", line 1888, in change_view
    return self.changeform_view(request, object_id, form_url, extra_context)
  File "/home/wartinich/.local/lib/python3.10/site-packages/django/utils/decorators.py", line 46, in _wrapper
    return bound_method(*args, **kwargs)
  File "/home/wartinich/.local/lib/python3.10/site-packages/django/utils/decorators.py", line 133, in _wrapped_view
    response = view_func(request, *args, **kwargs)
  File "/home/wartinich/.local/lib/python3.10/site-packages/django/contrib/admin/options.py", line 1745, in changeform_view
    return self._changeform_view(request, object_id, form_url, extra_context)
  File "/home/wartinich/.local/lib/python3.10/site-packages/django/contrib/admin/options.py", line 1781, in _changeform_view
    ModelForm = self.get_form(
  File "/home/wartinich/.local/lib/python3.10/site-packages/django/contrib/auth/admin.py", line 98, in get_form
    return super().get_form(request, obj, **defaults)
  File "/home/wartinich/.local/lib/python3.10/site-packages/django/contrib/admin/options.py", line 806, in get_form
    raise FieldError(
django.core.exceptions.FieldError: Unknown field(s) (show_avatar) specified for User. Check fields/fieldsets/exclude attributes of class UserAdmin.
ERROR [2022-06-14 05:56:13,572] - [django.server:log_message:187] "GET /admin/users/user/2/change/ HTTP/1.1" 500 140319
ERROR [2022-06-14 05:56:14,234] - [django.request:log_response:241] Internal Server Error: /admin/users/user/2/change/
Traceback (most recent call last):
  File "/home/wartinich/.local/lib/python3.10/site-packages/django/contrib/admin/options.py", line 804, in get_form
    return modelform_factory(self.model, **defaults)
  File "/home/wartinich/.local/lib/python3.10/site-packages/django/forms/models.py", line 648, in modelform_factory
    return type(form)(class_name, (form,), form_class_attrs)
  File "/home/wartinich/.local/lib/python3.10/site-packages/django/forms/models.py", line 327, in __new__
    raise FieldError(message)
django.core.exceptions.FieldError: Unknown field(s) (show_avatar) specified for User

During handling of the above exception, another exception occurred:

Traceback (most recent call last):
  File "/home/wartinich/.local/lib/python3.10/site-packages/django/core/handlers/exception.py", line 55, in inner
    response = get_response(request)
  File "/home/wartinich/.local/lib/python3.10/site-packages/django/core/handlers/base.py", line 197, in _get_response
    response = wrapped_callback(request, *callback_args, **callback_kwargs)
  File "/home/wartinich/.local/lib/python3.10/site-packages/django/contrib/admin/options.py", line 683, in wrapper
    return self.admin_site.admin_view(view)(*args, **kwargs)
  File "/home/wartinich/.local/lib/python3.10/site-packages/django/utils/decorators.py", line 133, in _wrapped_view
    response = view_func(request, *args, **kwargs)
  File "/home/wartinich/.local/lib/python3.10/site-packages/django/views/decorators/cache.py", line 62, in _wrapped_view_func
    response = view_func(request, *args, **kwargs)
  File "/home/wartinich/.local/lib/python3.10/site-packages/django/contrib/admin/sites.py", line 242, in inner
    return view(request, *args, **kwargs)
  File "/home/wartinich/.local/lib/python3.10/site-packages/django/contrib/admin/options.py", line 1888, in change_view
    return self.changeform_view(request, object_id, form_url, extra_context)
  File "/home/wartinich/.local/lib/python3.10/site-packages/django/utils/decorators.py", line 46, in _wrapper
    return bound_method(*args, **kwargs)
  File "/home/wartinich/.local/lib/python3.10/site-packages/django/utils/decorators.py", line 133, in _wrapped_view
    response = view_func(request, *args, **kwargs)
  File "/home/wartinich/.local/lib/python3.10/site-packages/django/contrib/admin/options.py", line 1745, in changeform_view
    return self._changeform_view(request, object_id, form_url, extra_context)
  File "/home/wartinich/.local/lib/python3.10/site-packages/django/contrib/admin/options.py", line 1781, in _changeform_view
    ModelForm = self.get_form(
  File "/home/wartinich/.local/lib/python3.10/site-packages/django/contrib/auth/admin.py", line 98, in get_form
    return super().get_form(request, obj, **defaults)
  File "/home/wartinich/.local/lib/python3.10/site-packages/django/contrib/admin/options.py", line 806, in get_form
    raise FieldError(
django.core.exceptions.FieldError: Unknown field(s) (show_avatar) specified for User. Check fields/fieldsets/exclude attributes of class UserAdmin.
ERROR [2022-06-14 05:56:14,235] - [django.server:log_message:187] "GET /admin/users/user/2/change/ HTTP/1.1" 500 140319
ERROR [2022-06-14 05:56:14,824] - [django.request:log_response:241] Internal Server Error: /admin/users/user/2/change/
Traceback (most recent call last):
  File "/home/wartinich/.local/lib/python3.10/site-packages/django/contrib/admin/options.py", line 804, in get_form
    return modelform_factory(self.model, **defaults)
  File "/home/wartinich/.local/lib/python3.10/site-packages/django/forms/models.py", line 648, in modelform_factory
    return type(form)(class_name, (form,), form_class_attrs)
  File "/home/wartinich/.local/lib/python3.10/site-packages/django/forms/models.py", line 327, in __new__
    raise FieldError(message)
django.core.exceptions.FieldError: Unknown field(s) (show_avatar) specified for User

During handling of the above exception, another exception occurred:

Traceback (most recent call last):
  File "/home/wartinich/.local/lib/python3.10/site-packages/django/core/handlers/exception.py", line 55, in inner
    response = get_response(request)
  File "/home/wartinich/.local/lib/python3.10/site-packages/django/core/handlers/base.py", line 197, in _get_response
    response = wrapped_callback(request, *callback_args, **callback_kwargs)
  File "/home/wartinich/.local/lib/python3.10/site-packages/django/contrib/admin/options.py", line 683, in wrapper
    return self.admin_site.admin_view(view)(*args, **kwargs)
  File "/home/wartinich/.local/lib/python3.10/site-packages/django/utils/decorators.py", line 133, in _wrapped_view
    response = view_func(request, *args, **kwargs)
  File "/home/wartinich/.local/lib/python3.10/site-packages/django/views/decorators/cache.py", line 62, in _wrapped_view_func
    response = view_func(request, *args, **kwargs)
  File "/home/wartinich/.local/lib/python3.10/site-packages/django/contrib/admin/sites.py", line 242, in inner
    return view(request, *args, **kwargs)
  File "/home/wartinich/.local/lib/python3.10/site-packages/django/contrib/admin/options.py", line 1888, in change_view
    return self.changeform_view(request, object_id, form_url, extra_context)
  File "/home/wartinich/.local/lib/python3.10/site-packages/django/utils/decorators.py", line 46, in _wrapper
    return bound_method(*args, **kwargs)
  File "/home/wartinich/.local/lib/python3.10/site-packages/django/utils/decorators.py", line 133, in _wrapped_view
    response = view_func(request, *args, **kwargs)
  File "/home/wartinich/.local/lib/python3.10/site-packages/django/contrib/admin/options.py", line 1745, in changeform_view
    return self._changeform_view(request, object_id, form_url, extra_context)
  File "/home/wartinich/.local/lib/python3.10/site-packages/django/contrib/admin/options.py", line 1781, in _changeform_view
    ModelForm = self.get_form(
  File "/home/wartinich/.local/lib/python3.10/site-packages/django/contrib/auth/admin.py", line 98, in get_form
    return super().get_form(request, obj, **defaults)
  File "/home/wartinich/.local/lib/python3.10/site-packages/django/contrib/admin/options.py", line 806, in get_form
    raise FieldError(
django.core.exceptions.FieldError: Unknown field(s) (show_avatar) specified for User. Check fields/fieldsets/exclude attributes of class UserAdmin.
ERROR [2022-06-14 05:56:14,824] - [django.server:log_message:187] "GET /admin/users/user/2/change/ HTTP/1.1" 500 140319
ERROR [2022-06-14 05:56:15,109] - [django.request:log_response:241] Internal Server Error: /admin/users/user/2/change/
Traceback (most recent call last):
  File "/home/wartinich/.local/lib/python3.10/site-packages/django/contrib/admin/options.py", line 804, in get_form
    return modelform_factory(self.model, **defaults)
  File "/home/wartinich/.local/lib/python3.10/site-packages/django/forms/models.py", line 648, in modelform_factory
    return type(form)(class_name, (form,), form_class_attrs)
  File "/home/wartinich/.local/lib/python3.10/site-packages/django/forms/models.py", line 327, in __new__
    raise FieldError(message)
django.core.exceptions.FieldError: Unknown field(s) (show_avatar) specified for User

During handling of the above exception, another exception occurred:

Traceback (most recent call last):
  File "/home/wartinich/.local/lib/python3.10/site-packages/django/core/handlers/exception.py", line 55, in inner
    response = get_response(request)
  File "/home/wartinich/.local/lib/python3.10/site-packages/django/core/handlers/base.py", line 197, in _get_response
    response = wrapped_callback(request, *callback_args, **callback_kwargs)
  File "/home/wartinich/.local/lib/python3.10/site-packages/django/contrib/admin/options.py", line 683, in wrapper
    return self.admin_site.admin_view(view)(*args, **kwargs)
  File "/home/wartinich/.local/lib/python3.10/site-packages/django/utils/decorators.py", line 133, in _wrapped_view
    response = view_func(request, *args, **kwargs)
  File "/home/wartinich/.local/lib/python3.10/site-packages/django/views/decorators/cache.py", line 62, in _wrapped_view_func
    response = view_func(request, *args, **kwargs)
  File "/home/wartinich/.local/lib/python3.10/site-packages/django/contrib/admin/sites.py", line 242, in inner
    return view(request, *args, **kwargs)
  File "/home/wartinich/.local/lib/python3.10/site-packages/django/contrib/admin/options.py", line 1888, in change_view
    return self.changeform_view(request, object_id, form_url, extra_context)
  File "/home/wartinich/.local/lib/python3.10/site-packages/django/utils/decorators.py", line 46, in _wrapper
    return bound_method(*args, **kwargs)
  File "/home/wartinich/.local/lib/python3.10/site-packages/django/utils/decorators.py", line 133, in _wrapped_view
    response = view_func(request, *args, **kwargs)
  File "/home/wartinich/.local/lib/python3.10/site-packages/django/contrib/admin/options.py", line 1745, in changeform_view
    return self._changeform_view(request, object_id, form_url, extra_context)
  File "/home/wartinich/.local/lib/python3.10/site-packages/django/contrib/admin/options.py", line 1781, in _changeform_view
    ModelForm = self.get_form(
  File "/home/wartinich/.local/lib/python3.10/site-packages/django/contrib/auth/admin.py", line 98, in get_form
    return super().get_form(request, obj, **defaults)
  File "/home/wartinich/.local/lib/python3.10/site-packages/django/contrib/admin/options.py", line 806, in get_form
    raise FieldError(
django.core.exceptions.FieldError: Unknown field(s) (show_avatar) specified for User. Check fields/fieldsets/exclude attributes of class UserAdmin.
ERROR [2022-06-14 05:56:15,111] - [django.server:log_message:187] "GET /admin/users/user/2/change/ HTTP/1.1" 500 140319
ERROR [2022-06-14 05:56:15,356] - [django.request:log_response:241] Internal Server Error: /admin/users/user/2/change/
Traceback (most recent call last):
  File "/home/wartinich/.local/lib/python3.10/site-packages/django/contrib/admin/options.py", line 804, in get_form
    return modelform_factory(self.model, **defaults)
  File "/home/wartinich/.local/lib/python3.10/site-packages/django/forms/models.py", line 648, in modelform_factory
    return type(form)(class_name, (form,), form_class_attrs)
  File "/home/wartinich/.local/lib/python3.10/site-packages/django/forms/models.py", line 327, in __new__
    raise FieldError(message)
django.core.exceptions.FieldError: Unknown field(s) (show_avatar) specified for User

During handling of the above exception, another exception occurred:

Traceback (most recent call last):
  File "/home/wartinich/.local/lib/python3.10/site-packages/django/core/handlers/exception.py", line 55, in inner
    response = get_response(request)
  File "/home/wartinich/.local/lib/python3.10/site-packages/django/core/handlers/base.py", line 197, in _get_response
    response = wrapped_callback(request, *callback_args, **callback_kwargs)
  File "/home/wartinich/.local/lib/python3.10/site-packages/django/contrib/admin/options.py", line 683, in wrapper
    return self.admin_site.admin_view(view)(*args, **kwargs)
  File "/home/wartinich/.local/lib/python3.10/site-packages/django/utils/decorators.py", line 133, in _wrapped_view
    response = view_func(request, *args, **kwargs)
  File "/home/wartinich/.local/lib/python3.10/site-packages/django/views/decorators/cache.py", line 62, in _wrapped_view_func
    response = view_func(request, *args, **kwargs)
  File "/home/wartinich/.local/lib/python3.10/site-packages/django/contrib/admin/sites.py", line 242, in inner
    return view(request, *args, **kwargs)
  File "/home/wartinich/.local/lib/python3.10/site-packages/django/contrib/admin/options.py", line 1888, in change_view
    return self.changeform_view(request, object_id, form_url, extra_context)
  File "/home/wartinich/.local/lib/python3.10/site-packages/django/utils/decorators.py", line 46, in _wrapper
    return bound_method(*args, **kwargs)
  File "/home/wartinich/.local/lib/python3.10/site-packages/django/utils/decorators.py", line 133, in _wrapped_view
    response = view_func(request, *args, **kwargs)
  File "/home/wartinich/.local/lib/python3.10/site-packages/django/contrib/admin/options.py", line 1745, in changeform_view
    return self._changeform_view(request, object_id, form_url, extra_context)
  File "/home/wartinich/.local/lib/python3.10/site-packages/django/contrib/admin/options.py", line 1781, in _changeform_view
    ModelForm = self.get_form(
  File "/home/wartinich/.local/lib/python3.10/site-packages/django/contrib/auth/admin.py", line 98, in get_form
    return super().get_form(request, obj, **defaults)
  File "/home/wartinich/.local/lib/python3.10/site-packages/django/contrib/admin/options.py", line 806, in get_form
    raise FieldError(
django.core.exceptions.FieldError: Unknown field(s) (show_avatar) specified for User. Check fields/fieldsets/exclude attributes of class UserAdmin.
ERROR [2022-06-14 05:56:15,357] - [django.server:log_message:187] "GET /admin/users/user/2/change/ HTTP/1.1" 500 140319
ERROR [2022-06-14 05:56:15,561] - [django.request:log_response:241] Internal Server Error: /admin/users/user/2/change/
Traceback (most recent call last):
  File "/home/wartinich/.local/lib/python3.10/site-packages/django/contrib/admin/options.py", line 804, in get_form
    return modelform_factory(self.model, **defaults)
  File "/home/wartinich/.local/lib/python3.10/site-packages/django/forms/models.py", line 648, in modelform_factory
    return type(form)(class_name, (form,), form_class_attrs)
  File "/home/wartinich/.local/lib/python3.10/site-packages/django/forms/models.py", line 327, in __new__
    raise FieldError(message)
django.core.exceptions.FieldError: Unknown field(s) (show_avatar) specified for User

During handling of the above exception, another exception occurred:

Traceback (most recent call last):
  File "/home/wartinich/.local/lib/python3.10/site-packages/django/core/handlers/exception.py", line 55, in inner
    response = get_response(request)
  File "/home/wartinich/.local/lib/python3.10/site-packages/django/core/handlers/base.py", line 197, in _get_response
    response = wrapped_callback(request, *callback_args, **callback_kwargs)
  File "/home/wartinich/.local/lib/python3.10/site-packages/django/contrib/admin/options.py", line 683, in wrapper
    return self.admin_site.admin_view(view)(*args, **kwargs)
  File "/home/wartinich/.local/lib/python3.10/site-packages/django/utils/decorators.py", line 133, in _wrapped_view
    response = view_func(request, *args, **kwargs)
  File "/home/wartinich/.local/lib/python3.10/site-packages/django/views/decorators/cache.py", line 62, in _wrapped_view_func
    response = view_func(request, *args, **kwargs)
  File "/home/wartinich/.local/lib/python3.10/site-packages/django/contrib/admin/sites.py", line 242, in inner
    return view(request, *args, **kwargs)
  File "/home/wartinich/.local/lib/python3.10/site-packages/django/contrib/admin/options.py", line 1888, in change_view
    return self.changeform_view(request, object_id, form_url, extra_context)
  File "/home/wartinich/.local/lib/python3.10/site-packages/django/utils/decorators.py", line 46, in _wrapper
    return bound_method(*args, **kwargs)
  File "/home/wartinich/.local/lib/python3.10/site-packages/django/utils/decorators.py", line 133, in _wrapped_view
    response = view_func(request, *args, **kwargs)
  File "/home/wartinich/.local/lib/python3.10/site-packages/django/contrib/admin/options.py", line 1745, in changeform_view
    return self._changeform_view(request, object_id, form_url, extra_context)
  File "/home/wartinich/.local/lib/python3.10/site-packages/django/contrib/admin/options.py", line 1781, in _changeform_view
    ModelForm = self.get_form(
  File "/home/wartinich/.local/lib/python3.10/site-packages/django/contrib/auth/admin.py", line 98, in get_form
    return super().get_form(request, obj, **defaults)
  File "/home/wartinich/.local/lib/python3.10/site-packages/django/contrib/admin/options.py", line 806, in get_form
    raise FieldError(
django.core.exceptions.FieldError: Unknown field(s) (show_avatar) specified for User. Check fields/fieldsets/exclude attributes of class UserAdmin.
ERROR [2022-06-14 05:56:15,562] - [django.server:log_message:187] "GET /admin/users/user/2/change/ HTTP/1.1" 500 140319
INFO [2022-06-14 05:56:53,975] - [django.utils.autoreload:trigger_reload:266] /home/wartinich/Projects/voice_generator/src/users/admin.py changed, reloading.
INFO [2022-06-14 05:56:54,467] - [django.utils.autoreload:run_with_reloader:677] Watching for file changes with StatReloader
INFO [2022-06-14 05:56:56,431] - [django.server:log_message:187] "GET /admin/users/user/ HTTP/1.1" 200 7976
INFO [2022-06-14 05:56:58,036] - [django.server:log_message:187] "GET /admin/users/user/ HTTP/1.1" 200 7976
INFO [2022-06-14 05:56:58,061] - [django.server:log_message:187] "GET /admin/jsi18n/ HTTP/1.1" 200 3343
INFO [2022-06-14 05:57:02,645] - [django.server:log_message:187] "GET /admin/users/user/2/change/ HTTP/1.1" 200 10451
INFO [2022-06-14 05:57:02,671] - [django.server:log_message:187] "GET /static/admin/css/forms.css HTTP/1.1" 200 8878
INFO [2022-06-14 05:57:02,673] - [django.server:log_message:187] "GET /static/admin/js/calendar.js HTTP/1.1" 200 8466
INFO [2022-06-14 05:57:02,680] - [django.server:log_message:187] "GET /static/admin/js/admin/DateTimeShortcuts.js HTTP/1.1" 200 19634
INFO [2022-06-14 05:57:02,681] - [django.server:log_message:187] "GET /static/admin/js/prepopulate_init.js HTTP/1.1" 200 492
INFO [2022-06-14 05:57:02,697] - [django.server:log_message:187] "GET /admin/jsi18n/ HTTP/1.1" 200 3343
INFO [2022-06-14 05:57:02,701] - [django.server:log_message:187] "GET /static/admin/js/change_form.js HTTP/1.1" 200 606
INFO [2022-06-14 05:57:02,729] - [django.server:log_message:187] "GET /static/admin/css/widgets.css HTTP/1.1" 200 11097
INFO [2022-06-14 05:57:02,830] - [django.server:log_message:187] "GET /static/admin/img/icon-calendar.svg HTTP/1.1" 200 1086
INFO [2022-06-14 05:57:56,364] - [django.utils.autoreload:trigger_reload:266] /home/wartinich/Projects/voice_generator/src/users/admin.py changed, reloading.
INFO [2022-06-14 05:57:56,939] - [django.utils.autoreload:run_with_reloader:677] Watching for file changes with StatReloader
ERROR [2022-06-14 05:57:58,174] - [django.request:log_response:241] Internal Server Error: /admin/users/user/2/change/
Traceback (most recent call last):
  File "/home/wartinich/.local/lib/python3.10/site-packages/django/contrib/admin/options.py", line 804, in get_form
    return modelform_factory(self.model, **defaults)
  File "/home/wartinich/.local/lib/python3.10/site-packages/django/forms/models.py", line 648, in modelform_factory
    return type(form)(class_name, (form,), form_class_attrs)
  File "/home/wartinich/.local/lib/python3.10/site-packages/django/forms/models.py", line 327, in __new__
    raise FieldError(message)
django.core.exceptions.FieldError: Unknown field(s) (show_avatar) specified for User

During handling of the above exception, another exception occurred:

Traceback (most recent call last):
  File "/home/wartinich/.local/lib/python3.10/site-packages/django/core/handlers/exception.py", line 55, in inner
    response = get_response(request)
  File "/home/wartinich/.local/lib/python3.10/site-packages/django/core/handlers/base.py", line 197, in _get_response
    response = wrapped_callback(request, *callback_args, **callback_kwargs)
  File "/home/wartinich/.local/lib/python3.10/site-packages/django/contrib/admin/options.py", line 683, in wrapper
    return self.admin_site.admin_view(view)(*args, **kwargs)
  File "/home/wartinich/.local/lib/python3.10/site-packages/django/utils/decorators.py", line 133, in _wrapped_view
    response = view_func(request, *args, **kwargs)
  File "/home/wartinich/.local/lib/python3.10/site-packages/django/views/decorators/cache.py", line 62, in _wrapped_view_func
    response = view_func(request, *args, **kwargs)
  File "/home/wartinich/.local/lib/python3.10/site-packages/django/contrib/admin/sites.py", line 242, in inner
    return view(request, *args, **kwargs)
  File "/home/wartinich/.local/lib/python3.10/site-packages/django/contrib/admin/options.py", line 1888, in change_view
    return self.changeform_view(request, object_id, form_url, extra_context)
  File "/home/wartinich/.local/lib/python3.10/site-packages/django/utils/decorators.py", line 46, in _wrapper
    return bound_method(*args, **kwargs)
  File "/home/wartinich/.local/lib/python3.10/site-packages/django/utils/decorators.py", line 133, in _wrapped_view
    response = view_func(request, *args, **kwargs)
  File "/home/wartinich/.local/lib/python3.10/site-packages/django/contrib/admin/options.py", line 1745, in changeform_view
    return self._changeform_view(request, object_id, form_url, extra_context)
  File "/home/wartinich/.local/lib/python3.10/site-packages/django/contrib/admin/options.py", line 1781, in _changeform_view
    ModelForm = self.get_form(
  File "/home/wartinich/.local/lib/python3.10/site-packages/django/contrib/auth/admin.py", line 98, in get_form
    return super().get_form(request, obj, **defaults)
  File "/home/wartinich/.local/lib/python3.10/site-packages/django/contrib/admin/options.py", line 806, in get_form
    raise FieldError(
django.core.exceptions.FieldError: Unknown field(s) (show_avatar) specified for User. Check fields/fieldsets/exclude attributes of class UserAdmin.
ERROR [2022-06-14 05:57:58,175] - [django.server:log_message:187] "GET /admin/users/user/2/change/ HTTP/1.1" 500 140248
INFO [2022-06-14 05:58:52,442] - [django.utils.autoreload:trigger_reload:266] /home/wartinich/Projects/voice_generator/src/users/admin.py changed, reloading.
INFO [2022-06-14 05:58:52,923] - [django.utils.autoreload:run_with_reloader:677] Watching for file changes with StatReloader
INFO [2022-06-14 05:59:06,313] - [django.utils.autoreload:trigger_reload:266] /home/wartinich/Projects/voice_generator/src/users/admin.py changed, reloading.
INFO [2022-06-14 05:59:06,954] - [django.utils.autoreload:run_with_reloader:677] Watching for file changes with StatReloader
ERROR [2022-06-14 05:59:08,826] - [django.request:log_response:241] Internal Server Error: /admin/users/user/2/change/
Traceback (most recent call last):
  File "/home/wartinich/.local/lib/python3.10/site-packages/django/contrib/admin/options.py", line 804, in get_form
    return modelform_factory(self.model, **defaults)
  File "/home/wartinich/.local/lib/python3.10/site-packages/django/forms/models.py", line 648, in modelform_factory
    return type(form)(class_name, (form,), form_class_attrs)
  File "/home/wartinich/.local/lib/python3.10/site-packages/django/forms/models.py", line 327, in __new__
    raise FieldError(message)
django.core.exceptions.FieldError: Unknown field(s) (show_avatar) specified for User

During handling of the above exception, another exception occurred:

Traceback (most recent call last):
  File "/home/wartinich/.local/lib/python3.10/site-packages/django/core/handlers/exception.py", line 55, in inner
    response = get_response(request)
  File "/home/wartinich/.local/lib/python3.10/site-packages/django/core/handlers/base.py", line 197, in _get_response
    response = wrapped_callback(request, *callback_args, **callback_kwargs)
  File "/home/wartinich/.local/lib/python3.10/site-packages/django/contrib/admin/options.py", line 683, in wrapper
    return self.admin_site.admin_view(view)(*args, **kwargs)
  File "/home/wartinich/.local/lib/python3.10/site-packages/django/utils/decorators.py", line 133, in _wrapped_view
    response = view_func(request, *args, **kwargs)
  File "/home/wartinich/.local/lib/python3.10/site-packages/django/views/decorators/cache.py", line 62, in _wrapped_view_func
    response = view_func(request, *args, **kwargs)
  File "/home/wartinich/.local/lib/python3.10/site-packages/django/contrib/admin/sites.py", line 242, in inner
    return view(request, *args, **kwargs)
  File "/home/wartinich/.local/lib/python3.10/site-packages/django/contrib/admin/options.py", line 1888, in change_view
    return self.changeform_view(request, object_id, form_url, extra_context)
  File "/home/wartinich/.local/lib/python3.10/site-packages/django/utils/decorators.py", line 46, in _wrapper
    return bound_method(*args, **kwargs)
  File "/home/wartinich/.local/lib/python3.10/site-packages/django/utils/decorators.py", line 133, in _wrapped_view
    response = view_func(request, *args, **kwargs)
  File "/home/wartinich/.local/lib/python3.10/site-packages/django/contrib/admin/options.py", line 1745, in changeform_view
    return self._changeform_view(request, object_id, form_url, extra_context)
  File "/home/wartinich/.local/lib/python3.10/site-packages/django/contrib/admin/options.py", line 1781, in _changeform_view
    ModelForm = self.get_form(
  File "/home/wartinich/.local/lib/python3.10/site-packages/django/contrib/auth/admin.py", line 98, in get_form
    return super().get_form(request, obj, **defaults)
  File "/home/wartinich/.local/lib/python3.10/site-packages/django/contrib/admin/options.py", line 806, in get_form
    raise FieldError(
django.core.exceptions.FieldError: Unknown field(s) (show_avatar) specified for User. Check fields/fieldsets/exclude attributes of class UserAdmin.
ERROR [2022-06-14 05:59:08,827] - [django.server:log_message:187] "GET /admin/users/user/2/change/ HTTP/1.1" 500 140248
INFO [2022-06-14 05:59:38,172] - [django.utils.autoreload:trigger_reload:266] /home/wartinich/Projects/voice_generator/src/users/admin.py changed, reloading.
INFO [2022-06-14 05:59:38,636] - [django.utils.autoreload:run_with_reloader:677] Watching for file changes with StatReloader
INFO [2022-06-14 05:59:40,034] - [django.server:log_message:187] "GET /admin/users/user/2/change/ HTTP/1.1" 200 10970
INFO [2022-06-14 05:59:40,061] - [django.server:log_message:187] "GET /admin/jsi18n/ HTTP/1.1" 200 3343
INFO [2022-06-14 06:00:10,865] - [django.utils.autoreload:trigger_reload:266] /home/wartinich/Projects/voice_generator/src/users/admin.py changed, reloading.
INFO [2022-06-14 06:00:11,407] - [django.utils.autoreload:run_with_reloader:677] Watching for file changes with StatReloader
INFO [2022-06-14 06:03:11,718] - [django.utils.autoreload:run_with_reloader:677] Watching for file changes with StatReloader
WARNING [2022-06-14 06:03:55,237] - [django.request:log_response:241] Not Found: /
WARNING [2022-06-14 06:03:55,238] - [django.server:log_message:187] "GET / HTTP/1.1" 404 4211
INFO [2022-06-14 06:04:00,974] - [django.server:log_message:187] "GET /login/ HTTP/1.1" 200 1047
INFO [2022-06-14 06:04:19,208] - [django.server:log_message:187] "POST /login/ HTTP/1.1" 200 12
INFO [2022-06-14 06:06:47,224] - [django.utils.autoreload:trigger_reload:266] /home/wartinich/Projects/voice_generator/src/users/views.py changed, reloading.
INFO [2022-06-14 06:06:47,790] - [django.utils.autoreload:run_with_reloader:677] Watching for file changes with StatReloader
INFO [2022-06-14 06:10:08,799] - [django.utils.autoreload:trigger_reload:266] /home/wartinich/Projects/voice_generator/src/users/views.py changed, reloading.
INFO [2022-06-14 06:10:09,364] - [django.utils.autoreload:run_with_reloader:677] Watching for file changes with StatReloader
INFO [2022-06-14 06:10:40,232] - [django.utils.autoreload:trigger_reload:266] /home/wartinich/Projects/voice_generator/src/users/views.py changed, reloading.
INFO [2022-06-14 06:10:41,039] - [django.utils.autoreload:run_with_reloader:677] Watching for file changes with StatReloader
INFO [2022-06-14 06:11:29,274] - [django.utils.autoreload:trigger_reload:266] /home/wartinich/Projects/voice_generator/src/users/views.py changed, reloading.
INFO [2022-06-14 06:11:30,022] - [django.utils.autoreload:run_with_reloader:677] Watching for file changes with StatReloader
INFO [2022-06-14 06:11:48,665] - [django.utils.autoreload:trigger_reload:266] /home/wartinich/Projects/voice_generator/src/users/urls.py changed, reloading.
INFO [2022-06-14 06:11:49,213] - [django.utils.autoreload:run_with_reloader:677] Watching for file changes with StatReloader
ERROR [2022-06-14 06:11:51,210] - [django.request:log_response:241] Internal Server Error: /login/
Traceback (most recent call last):
  File "/home/wartinich/.local/lib/python3.10/site-packages/django/core/handlers/exception.py", line 55, in inner
    response = get_response(request)
  File "/home/wartinich/.local/lib/python3.10/site-packages/django/core/handlers/base.py", line 197, in _get_response
    response = wrapped_callback(request, *callback_args, **callback_kwargs)
  File "/home/wartinich/Projects/voice_generator/src/users/views.py", line 34, in LoginPageView
    return render(request=request, template_name="main/login.html", context={"login_form":form})
  File "/home/wartinich/.local/lib/python3.10/site-packages/django/shortcuts.py", line 24, in render
    content = loader.render_to_string(template_name, context, request, using=using)
  File "/home/wartinich/.local/lib/python3.10/site-packages/django/template/loader.py", line 61, in render_to_string
    template = get_template(template_name, using=using)
  File "/home/wartinich/.local/lib/python3.10/site-packages/django/template/loader.py", line 19, in get_template
    raise TemplateDoesNotExist(template_name, chain=chain)
django.template.exceptions.TemplateDoesNotExist: main/login.html
ERROR [2022-06-14 06:11:51,211] - [django.server:log_message:187] "GET /login/ HTTP/1.1" 500 82360
INFO [2022-06-14 06:12:06,018] - [django.utils.autoreload:trigger_reload:266] /home/wartinich/Projects/voice_generator/src/users/views.py changed, reloading.
INFO [2022-06-14 06:12:06,498] - [django.utils.autoreload:run_with_reloader:677] Watching for file changes with StatReloader
INFO [2022-06-14 06:12:08,253] - [django.server:log_message:187] "GET /login/ HTTP/1.1" 200 613
INFO [2022-06-14 06:12:23,234] - [django.utils.autoreload:trigger_reload:266] /home/wartinich/Projects/voice_generator/src/users/views.py changed, reloading.
INFO [2022-06-14 06:12:23,691] - [django.utils.autoreload:run_with_reloader:677] Watching for file changes with StatReloader
INFO [2022-06-14 06:12:25,529] - [django.server:log_message:187] "GET /login/ HTTP/1.1" 200 1006
ERROR [2022-06-14 06:12:29,893] - [django.request:log_response:241] Internal Server Error: /login/
Traceback (most recent call last):
  File "/home/wartinich/.local/lib/python3.10/site-packages/django/core/handlers/exception.py", line 55, in inner
    response = get_response(request)
  File "/home/wartinich/.local/lib/python3.10/site-packages/django/core/handlers/base.py", line 197, in _get_response
    response = wrapped_callback(request, *callback_args, **callback_kwargs)
  File "/home/wartinich/Projects/voice_generator/src/users/views.py", line 27, in LoginPageView
    messages.info(request, f"You are now logged in as {username}.")
NameError: name 'messages' is not defined
ERROR [2022-06-14 06:12:29,894] - [django.server:log_message:187] "POST /login/ HTTP/1.1" 500 68174
INFO [2022-06-14 06:13:08,114] - [django.utils.autoreload:trigger_reload:266] /home/wartinich/Projects/voice_generator/src/users/views.py changed, reloading.
INFO [2022-06-14 06:13:08,576] - [django.utils.autoreload:run_with_reloader:677] Watching for file changes with StatReloader
WARNING [2022-06-14 06:13:11,233] - [django.security.csrf:log_response:241] Forbidden (CSRF token from POST incorrect.): /login/
WARNING [2022-06-14 06:13:11,234] - [django.server:log_message:187] "POST /login/ HTTP/1.1" 403 2518
INFO [2022-06-14 06:13:14,585] - [django.server:log_message:187] "GET /login/ HTTP/1.1" 200 1006
ERROR [2022-06-14 06:13:16,423] - [django.request:log_response:241] Internal Server Error: /login/
Traceback (most recent call last):
  File "/home/wartinich/.local/lib/python3.10/site-packages/django/urls/base.py", line 71, in reverse
    extra, resolver = resolver.namespace_dict[ns]
KeyError: 'main'

During handling of the above exception, another exception occurred:

Traceback (most recent call last):
  File "/home/wartinich/.local/lib/python3.10/site-packages/django/core/handlers/exception.py", line 55, in inner
    response = get_response(request)
  File "/home/wartinich/.local/lib/python3.10/site-packages/django/core/handlers/base.py", line 197, in _get_response
    response = wrapped_callback(request, *callback_args, **callback_kwargs)
  File "/home/wartinich/Projects/voice_generator/src/users/views.py", line 29, in LoginPageView
    return redirect("main:homepage")
  File "/home/wartinich/.local/lib/python3.10/site-packages/django/shortcuts.py", line 48, in redirect
    return redirect_class(resolve_url(to, *args, **kwargs))
  File "/home/wartinich/.local/lib/python3.10/site-packages/django/shortcuts.py", line 145, in resolve_url
    return reverse(to, args=args, kwargs=kwargs)
  File "/home/wartinich/.local/lib/python3.10/site-packages/django/urls/base.py", line 82, in reverse
    raise NoReverseMatch("%s is not a registered namespace" % key)
django.urls.exceptions.NoReverseMatch: 'main' is not a registered namespace
ERROR [2022-06-14 06:13:16,424] - [django.server:log_message:187] "POST /login/ HTTP/1.1" 500 88805
INFO [2022-06-14 06:13:28,499] - [django.utils.autoreload:trigger_reload:266] /home/wartinich/Projects/voice_generator/src/users/views.py changed, reloading.
INFO [2022-06-14 06:13:28,969] - [django.utils.autoreload:run_with_reloader:677] Watching for file changes with StatReloader
WARNING [2022-06-14 06:13:31,119] - [django.security.csrf:log_response:241] Forbidden (CSRF token from POST incorrect.): /login/
WARNING [2022-06-14 06:13:31,119] - [django.server:log_message:187] "POST /login/ HTTP/1.1" 403 2518
INFO [2022-06-14 06:13:33,113] - [django.server:log_message:187] "GET /login/ HTTP/1.1" 200 1006
ERROR [2022-06-14 06:13:34,754] - [django.request:log_response:241] Internal Server Error: /login/
Traceback (most recent call last):
  File "/home/wartinich/.local/lib/python3.10/site-packages/django/core/handlers/exception.py", line 55, in inner
    response = get_response(request)
  File "/home/wartinich/.local/lib/python3.10/site-packages/django/core/handlers/base.py", line 197, in _get_response
    response = wrapped_callback(request, *callback_args, **callback_kwargs)
  File "/home/wartinich/Projects/voice_generator/src/users/views.py", line 29, in LoginPageView
    return redirect("admin")
  File "/home/wartinich/.local/lib/python3.10/site-packages/django/shortcuts.py", line 48, in redirect
    return redirect_class(resolve_url(to, *args, **kwargs))
  File "/home/wartinich/.local/lib/python3.10/site-packages/django/shortcuts.py", line 145, in resolve_url
    return reverse(to, args=args, kwargs=kwargs)
  File "/home/wartinich/.local/lib/python3.10/site-packages/django/urls/base.py", line 88, in reverse
    return resolver._reverse_with_prefix(view, prefix, *args, **kwargs)
  File "/home/wartinich/.local/lib/python3.10/site-packages/django/urls/resolvers.py", line 802, in _reverse_with_prefix
    raise NoReverseMatch(msg)
django.urls.exceptions.NoReverseMatch: Reverse for 'admin' not found. 'admin' is not a valid view function or pattern name.
ERROR [2022-06-14 06:13:34,757] - [django.server:log_message:187] "POST /login/ HTTP/1.1" 500 87033
INFO [2022-06-14 06:13:59,250] - [django.utils.autoreload:trigger_reload:266] /home/wartinich/Projects/voice_generator/src/users/forms.py changed, reloading.
INFO [2022-06-14 06:13:59,852] - [django.utils.autoreload:run_with_reloader:677] Watching for file changes with StatReloader
INFO [2022-06-14 06:14:21,758] - [django.utils.autoreload:trigger_reload:266] /home/wartinich/Projects/voice_generator/src/users/views.py changed, reloading.
INFO [2022-06-14 06:14:22,339] - [django.utils.autoreload:run_with_reloader:677] Watching for file changes with StatReloader
WARNING [2022-06-14 06:14:24,955] - [django.security.csrf:log_response:241] Forbidden (CSRF token from POST incorrect.): /login/
WARNING [2022-06-14 06:14:24,956] - [django.server:log_message:187] "POST /login/ HTTP/1.1" 403 2518
INFO [2022-06-14 06:14:27,099] - [django.server:log_message:187] "GET /login/ HTTP/1.1" 200 1047
INFO [2022-06-14 06:15:42,603] - [django.utils.autoreload:trigger_reload:266] /home/wartinich/Projects/voice_generator/src/users/views.py changed, reloading.
INFO [2022-06-14 06:15:43,114] - [django.utils.autoreload:run_with_reloader:677] Watching for file changes with StatReloader
INFO [2022-06-14 06:16:38,581] - [django.utils.autoreload:trigger_reload:266] /home/wartinich/Projects/voice_generator/src/users/views.py changed, reloading.
INFO [2022-06-14 06:16:39,327] - [django.utils.autoreload:run_with_reloader:677] Watching for file changes with StatReloader
INFO [2022-06-14 06:16:47,790] - [django.utils.autoreload:trigger_reload:266] /home/wartinich/Projects/voice_generator/src/users/urls.py changed, reloading.
INFO [2022-06-14 06:16:48,421] - [django.utils.autoreload:run_with_reloader:677] Watching for file changes with StatReloader
INFO [2022-06-14 06:16:49,374] - [django.server:log_message:187] "GET /login/ HTTP/1.1" 200 1047
INFO [2022-06-14 06:17:02,578] - [django.server:log_message:187] "POST /login/ HTTP/1.1" 200 1047
INFO [2022-06-14 06:17:30,807] - [django.utils.autoreload:trigger_reload:266] /home/wartinich/Projects/voice_generator/src/users/views.py changed, reloading.
INFO [2022-06-14 06:17:31,344] - [django.utils.autoreload:run_with_reloader:677] Watching for file changes with StatReloader
INFO [2022-06-14 06:17:45,622] - [django.server:log_message:187] "POST /login/ HTTP/1.1" 200 1047
INFO [2022-06-14 06:18:17,993] - [django.utils.autoreload:trigger_reload:266] /home/wartinich/Projects/voice_generator/src/users/views.py changed, reloading.
INFO [2022-06-14 06:18:18,832] - [django.utils.autoreload:run_with_reloader:677] Watching for file changes with StatReloader
INFO [2022-06-14 06:18:22,085] - [django.utils.autoreload:trigger_reload:266] /home/wartinich/Projects/voice_generator/src/users/urls.py changed, reloading.
INFO [2022-06-14 06:18:22,703] - [django.utils.autoreload:run_with_reloader:677] Watching for file changes with StatReloader
ERROR [2022-06-14 06:18:25,160] - [django.request:log_response:241] Internal Server Error: /login/
Traceback (most recent call last):
  File "/home/wartinich/.local/lib/python3.10/site-packages/django/core/handlers/exception.py", line 55, in inner
    response = get_response(request)
  File "/home/wartinich/.local/lib/python3.10/site-packages/django/core/handlers/base.py", line 197, in _get_response
    response = wrapped_callback(request, *callback_args, **callback_kwargs)
  File "/home/wartinich/Projects/voice_generator/src/users/views.py", line 29, in LoginPageView
    return redirect("admin")
  File "/home/wartinich/.local/lib/python3.10/site-packages/django/shortcuts.py", line 48, in redirect
    return redirect_class(resolve_url(to, *args, **kwargs))
  File "/home/wartinich/.local/lib/python3.10/site-packages/django/shortcuts.py", line 145, in resolve_url
    return reverse(to, args=args, kwargs=kwargs)
  File "/home/wartinich/.local/lib/python3.10/site-packages/django/urls/base.py", line 88, in reverse
    return resolver._reverse_with_prefix(view, prefix, *args, **kwargs)
  File "/home/wartinich/.local/lib/python3.10/site-packages/django/urls/resolvers.py", line 802, in _reverse_with_prefix
    raise NoReverseMatch(msg)
django.urls.exceptions.NoReverseMatch: Reverse for 'admin' not found. 'admin' is not a valid view function or pattern name.
ERROR [2022-06-14 06:18:25,162] - [django.server:log_message:187] "POST /login/ HTTP/1.1" 500 87310
INFO [2022-06-14 06:18:57,895] - [django.utils.autoreload:trigger_reload:266] /home/wartinich/Projects/voice_generator/src/users/views.py changed, reloading.
INFO [2022-06-14 06:18:58,517] - [django.utils.autoreload:run_with_reloader:677] Watching for file changes with StatReloader
WARNING [2022-06-14 06:19:00,289] - [django.security.csrf:log_response:241] Forbidden (CSRF token from POST incorrect.): /login/
WARNING [2022-06-14 06:19:00,290] - [django.server:log_message:187] "POST /login/ HTTP/1.1" 403 2518
INFO [2022-06-14 06:19:04,464] - [django.server:log_message:187] "GET /login/ HTTP/1.1" 200 1047
INFO [2022-06-14 06:19:07,551] - [django.server:log_message:187] "POST /login/ HTTP/1.1" 302 0
INFO [2022-06-14 06:19:07,558] - [django.server:log_message:187] "GET /swagger/ HTTP/1.1" 200 2232
INFO [2022-06-14 06:19:07,586] - [django.server:log_message:187] "GET /static/drf-yasg/style.css HTTP/1.1" 304 0
INFO [2022-06-14 06:19:07,587] - [django.server:log_message:187] "GET /static/drf-yasg/swagger-ui-dist/swagger-ui.css HTTP/1.1" 304 0
INFO [2022-06-14 06:19:07,590] - [django.server:log_message:187] "GET /static/drf-yasg/url-polyfill.min.js HTTP/1.1" 304 0
INFO [2022-06-14 06:19:07,610] - [django.server:log_message:187] "GET /static/drf-yasg/insQ.min.js HTTP/1.1" 304 0
INFO [2022-06-14 06:19:07,611] - [django.server:log_message:187] "GET /static/drf-yasg/swagger-ui-init.js HTTP/1.1" 304 0
INFO [2022-06-14 06:19:07,612] - [django.server:log_message:187] "GET /static/drf-yasg/swagger-ui-dist/swagger-ui-bundle.js HTTP/1.1" 304 0
INFO [2022-06-14 06:19:07,612] - [django.server:log_message:187] "GET /static/drf-yasg/immutable.min.js HTTP/1.1" 304 0
INFO [2022-06-14 06:19:07,613] - [django.server:log_message:187] "GET /static/drf-yasg/swagger-ui-dist/swagger-ui-standalone-preset.js HTTP/1.1" 304 0
INFO [2022-06-14 06:19:07,772] - [django.server:log_message:187] "GET /swagger/?format=openapi HTTP/1.1" 200 2302
INFO [2022-06-14 06:21:05,056] - [django.utils.autoreload:trigger_reload:266] /home/wartinich/Projects/voice_generator/src/users/views.py changed, reloading.
INFO [2022-06-14 06:21:05,682] - [django.utils.autoreload:run_with_reloader:677] Watching for file changes with StatReloader
INFO [2022-06-14 06:21:31,641] - [django.utils.autoreload:trigger_reload:266] /home/wartinich/Projects/voice_generator/src/users/urls.py changed, reloading.
INFO [2022-06-14 06:21:32,279] - [django.utils.autoreload:run_with_reloader:677] Watching for file changes with StatReloader
INFO [2022-06-14 06:21:34,690] - [django.server:log_message:187] "GET /logout/ HTTP/1.1" 200 613
INFO [2022-06-14 06:21:43,591] - [django.server:log_message:187] "GET /login/ HTTP/1.1" 200 1047
ERROR [2022-06-14 06:21:56,032] - [django.request:log_response:241] Internal Server Error: /login/
Traceback (most recent call last):
  File "/home/wartinich/.local/lib/python3.10/site-packages/django/core/handlers/exception.py", line 55, in inner
    response = get_response(request)
  File "/home/wartinich/.local/lib/python3.10/site-packages/django/core/handlers/base.py", line 197, in _get_response
    response = wrapped_callback(request, *callback_args, **callback_kwargs)
  File "/home/wartinich/.local/lib/python3.10/site-packages/django/views/generic/base.py", line 84, in view
    return self.dispatch(request, *args, **kwargs)
  File "/home/wartinich/.local/lib/python3.10/site-packages/django/views/generic/base.py", line 119, in dispatch
    return handler(request, *args, **kwargs)
  File "/home/wartinich/Projects/voice_generator/src/users/views.py", line 65, in post
    'form': self.form_class
AttributeError: 'LoginPageView' object has no attribute 'form_class'
ERROR [2022-06-14 06:21:56,033] - [django.server:log_message:187] "POST /login/ HTTP/1.1" 500 76717
INFO [2022-06-14 06:22:16,011] - [django.utils.autoreload:trigger_reload:266] /home/wartinich/Projects/voice_generator/src/users/views.py changed, reloading.
INFO [2022-06-14 06:22:16,471] - [django.utils.autoreload:run_with_reloader:677] Watching for file changes with StatReloader
INFO [2022-06-14 06:22:20,868] - [django.server:log_message:187] "POST /login/ HTTP/1.1" 200 1047
INFO [2022-06-14 06:22:33,837] - [django.server:log_message:187] "POST /login/ HTTP/1.1" 200 1047
INFO [2022-06-14 06:23:03,003] - [django.utils.autoreload:trigger_reload:266] /home/wartinich/Projects/voice_generator/src/users/views.py changed, reloading.
INFO [2022-06-14 06:23:03,537] - [django.utils.autoreload:run_with_reloader:677] Watching for file changes with StatReloader
ERROR [2022-06-14 06:23:19,413] - [django.request:log_response:241] Internal Server Error: /login/
Traceback (most recent call last):
  File "/home/wartinich/.local/lib/python3.10/site-packages/django/core/handlers/exception.py", line 55, in inner
    response = get_response(request)
  File "/home/wartinich/.local/lib/python3.10/site-packages/django/core/handlers/base.py", line 197, in _get_response
    response = wrapped_callback(request, *callback_args, **callback_kwargs)
  File "/home/wartinich/.local/lib/python3.10/site-packages/django/views/generic/base.py", line 84, in view
    return self.dispatch(request, *args, **kwargs)
  File "/home/wartinich/.local/lib/python3.10/site-packages/django/views/generic/base.py", line 119, in dispatch
    return handler(request, *args, **kwargs)
  File "/home/wartinich/Projects/voice_generator/src/users/views.py", line 58, in post
    return redirect("admin")
  File "/home/wartinich/.local/lib/python3.10/site-packages/django/shortcuts.py", line 48, in redirect
    return redirect_class(resolve_url(to, *args, **kwargs))
  File "/home/wartinich/.local/lib/python3.10/site-packages/django/shortcuts.py", line 145, in resolve_url
    return reverse(to, args=args, kwargs=kwargs)
  File "/home/wartinich/.local/lib/python3.10/site-packages/django/urls/base.py", line 88, in reverse
    return resolver._reverse_with_prefix(view, prefix, *args, **kwargs)
  File "/home/wartinich/.local/lib/python3.10/site-packages/django/urls/resolvers.py", line 802, in _reverse_with_prefix
    raise NoReverseMatch(msg)
django.urls.exceptions.NoReverseMatch: Reverse for 'admin' not found. 'admin' is not a valid view function or pattern name.
ERROR [2022-06-14 06:23:19,418] - [django.server:log_message:187] "POST /login/ HTTP/1.1" 500 96345
INFO [2022-06-14 06:23:44,043] - [django.utils.autoreload:trigger_reload:266] /home/wartinich/Projects/voice_generator/src/users/views.py changed, reloading.
INFO [2022-06-14 06:23:44,689] - [django.utils.autoreload:run_with_reloader:677] Watching for file changes with StatReloader
WARNING [2022-06-14 06:23:46,216] - [django.security.csrf:log_response:241] Forbidden (CSRF token from POST incorrect.): /login/
WARNING [2022-06-14 06:23:46,217] - [django.server:log_message:187] "POST /login/ HTTP/1.1" 403 2518
INFO [2022-06-14 06:23:48,238] - [django.server:log_message:187] "GET /login/ HTTP/1.1" 200 1047
INFO [2022-06-14 06:23:50,050] - [django.server:log_message:187] "POST /login/ HTTP/1.1" 302 0
INFO [2022-06-14 06:23:50,057] - [django.server:log_message:187] "GET /swagger/ HTTP/1.1" 200 2232
INFO [2022-06-14 06:23:50,269] - [django.server:log_message:187] "GET /swagger/?format=openapi HTTP/1.1" 200 2302
INFO [2022-06-14 06:25:23,503] - [django.utils.autoreload:trigger_reload:266] /home/wartinich/Projects/voice_generator/src/users/views.py changed, reloading.
INFO [2022-06-14 06:25:24,113] - [django.utils.autoreload:run_with_reloader:677] Watching for file changes with StatReloader
INFO [2022-06-14 06:25:24,788] - [django.server:log_message:187] "GET /login/ HTTP/1.1" 200 1047
INFO [2022-06-14 06:25:26,574] - [django.server:log_message:187] "POST /login/ HTTP/1.1" 302 0
INFO [2022-06-14 06:25:26,581] - [django.server:log_message:187] "GET /swagger/ HTTP/1.1" 200 2232
INFO [2022-06-14 06:25:26,712] - [django.server:log_message:187] "GET /swagger/?format=openapi HTTP/1.1" 200 2302
INFO [2022-06-14 06:26:10,497] - [django.utils.autoreload:trigger_reload:266] /home/wartinich/Projects/voice_generator/src/users/views.py changed, reloading.
INFO [2022-06-14 06:26:11,149] - [django.utils.autoreload:run_with_reloader:677] Watching for file changes with StatReloader
INFO [2022-06-14 06:26:12,401] - [django.server:log_message:187] "GET /swagger/ HTTP/1.1" 200 2232
INFO [2022-06-14 06:26:12,566] - [django.server:log_message:187] "GET /swagger/?format=openapi HTTP/1.1" 200 2302
INFO [2022-06-14 06:26:12,571] - [django.server:log_message:187] "GET /static/drf-yasg/swagger-ui-dist/favicon-32x32.png HTTP/1.1" 200 628
INFO [2022-06-14 06:26:13,085] - [django.server:log_message:187] "GET /login/ HTTP/1.1" 200 1047
INFO [2022-06-14 06:26:15,001] - [django.server:log_message:187] "POST /login/ HTTP/1.1" 302 0
INFO [2022-06-14 06:26:15,008] - [django.server:log_message:187] "GET /swagger/ HTTP/1.1" 200 2232
INFO [2022-06-14 06:26:15,131] - [django.server:log_message:187] "GET /swagger/?format=openapi HTTP/1.1" 200 2302
INFO [2022-06-14 06:27:14,986] - [django.utils.autoreload:trigger_reload:266] /home/wartinich/Projects/voice_generator/src/users/views.py changed, reloading.
INFO [2022-06-14 06:27:15,629] - [django.utils.autoreload:run_with_reloader:677] Watching for file changes with StatReloader
INFO [2022-06-14 06:27:27,240] - [django.utils.autoreload:trigger_reload:266] /home/wartinich/Projects/voice_generator/src/users/views.py changed, reloading.
INFO [2022-06-14 06:27:27,677] - [django.utils.autoreload:run_with_reloader:677] Watching for file changes with StatReloader
INFO [2022-06-14 06:30:56,849] - [django.utils.autoreload:trigger_reload:266] /home/wartinich/Projects/voice_generator/src/users/views.py changed, reloading.
INFO [2022-06-14 06:30:57,728] - [django.utils.autoreload:run_with_reloader:677] Watching for file changes with StatReloader
INFO [2022-06-14 06:31:30,662] - [django.utils.autoreload:trigger_reload:266] /home/wartinich/Projects/voice_generator/src/users/views.py changed, reloading.
INFO [2022-06-14 06:31:31,160] - [django.utils.autoreload:run_with_reloader:677] Watching for file changes with StatReloader
INFO [2022-06-14 06:32:17,440] - [django.utils.autoreload:trigger_reload:266] /home/wartinich/Projects/voice_generator/src/users/views.py changed, reloading.
INFO [2022-06-14 06:32:17,937] - [django.utils.autoreload:run_with_reloader:677] Watching for file changes with StatReloader
INFO [2022-06-14 06:33:07,146] - [django.utils.autoreload:trigger_reload:266] /home/wartinich/Projects/voice_generator/src/users/views.py changed, reloading.
INFO [2022-06-14 06:33:07,680] - [django.utils.autoreload:run_with_reloader:677] Watching for file changes with StatReloader
INFO [2022-06-14 06:33:22,114] - [django.utils.autoreload:trigger_reload:266] /home/wartinich/Projects/voice_generator/src/users/urls.py changed, reloading.
INFO [2022-06-14 06:33:23,105] - [django.utils.autoreload:run_with_reloader:677] Watching for file changes with StatReloader
INFO [2022-06-14 06:33:47,773] - [django.utils.autoreload:trigger_reload:266] /home/wartinich/Projects/voice_generator/src/users/urls.py changed, reloading.
INFO [2022-06-14 06:33:48,272] - [django.utils.autoreload:run_with_reloader:677] Watching for file changes with StatReloader
INFO [2022-06-14 06:33:57,762] - [django.utils.autoreload:trigger_reload:266] /home/wartinich/Projects/voice_generator/src/users/urls.py changed, reloading.
INFO [2022-06-14 06:33:58,282] - [django.utils.autoreload:run_with_reloader:677] Watching for file changes with StatReloader
INFO [2022-06-14 06:34:15,786] - [django.utils.autoreload:trigger_reload:266] /home/wartinich/Projects/voice_generator/src/users/urls.py changed, reloading.
INFO [2022-06-14 06:34:16,268] - [django.utils.autoreload:run_with_reloader:677] Watching for file changes with StatReloader
INFO [2022-06-14 06:34:18,585] - [django.server:log_message:187] "GET /sign_up/ HTTP/1.1" 200 1943
INFO [2022-06-14 06:36:21,355] - [django.utils.autoreload:run_with_reloader:677] Watching for file changes with StatReloader
INFO [2022-06-14 06:36:45,188] - [django.utils.autoreload:trigger_reload:266] /home/wartinich/Projects/voice_generator/src/users/views.py changed, reloading.
INFO [2022-06-14 06:36:45,704] - [django.utils.autoreload:run_with_reloader:677] Watching for file changes with StatReloader
INFO [2022-06-14 06:38:52,663] - [django.server:log_message:187] "GET /login/ HTTP/1.1" 200 829
INFO [2022-06-14 06:43:23,419] - [django.server:log_message:187] "GET /login/ HTTP/1.1" 200 912
INFO [2022-06-14 06:44:25,159] - [django.server:log_message:187] "GET /login/ HTTP/1.1" 200 902
INFO [2022-06-14 06:44:31,084] - [django.server:log_message:187] "GET /login/ HTTP/1.1" 200 902
INFO [2022-06-14 06:45:19,648] - [django.server:log_message:187] "GET /login/ HTTP/1.1" 200 918
INFO [2022-06-14 06:45:34,752] - [django.server:log_message:187] "GET /login/ HTTP/1.1" 200 918
INFO [2022-06-14 06:45:41,451] - [django.server:log_message:187] "GET /login/ HTTP/1.1" 200 918
INFO [2022-06-14 06:45:49,733] - [django.server:log_message:187] "GET /login/ HTTP/1.1" 200 918
INFO [2022-06-14 06:46:04,905] - [django.server:log_message:187] "GET /login/ HTTP/1.1" 200 930
INFO [2022-06-14 06:48:22,318] - [django.server:log_message:187] "GET /login/ HTTP/1.1" 200 966
INFO [2022-06-14 06:50:22,108] - [django.server:log_message:187] "GET /login/ HTTP/1.1" 200 994
INFO [2022-06-14 06:50:22,709] - [django.server:log_message:187] "GET /login/ HTTP/1.1" 200 994
INFO [2022-06-14 06:50:22,877] - [django.server:log_message:187] "GET /login/ HTTP/1.1" 200 994
INFO [2022-06-14 06:51:05,994] - [django.server:log_message:187] "GET /login/ HTTP/1.1" 200 992
INFO [2022-06-14 06:51:06,429] - [django.server:log_message:187] "GET /login/ HTTP/1.1" 200 992
INFO [2022-06-14 06:54:36,252] - [django.server:log_message:187] "GET /login/ HTTP/1.1" 200 1026
INFO [2022-06-14 06:56:06,478] - [django.server:log_message:187] "GET /login/ HTTP/1.1" 200 1026
INFO [2022-06-14 06:56:06,893] - [django.server:log_message:187] "GET /login/ HTTP/1.1" 200 1026
INFO [2022-06-14 06:56:29,774] - [django.server:log_message:187] "GET /login/ HTTP/1.1" 200 1038
INFO [2022-06-14 06:57:19,689] - [django.server:log_message:187] "GET /login/ HTTP/1.1" 200 1054
INFO [2022-06-14 06:58:05,581] - [django.server:log_message:187] "GET /login/ HTTP/1.1" 200 1061
INFO [2022-06-14 06:58:18,700] - [django.server:log_message:187] "GET /login/ HTTP/1.1" 200 1058
INFO [2022-06-14 07:00:41,211] - [django.server:log_message:187] "GET /login/ HTTP/1.1" 200 1108
INFO [2022-06-14 07:01:52,736] - [django.server:log_message:187] "GET /login/ HTTP/1.1" 200 1159
INFO [2022-06-14 07:02:33,074] - [django.server:log_message:187] "GET /login/ HTTP/1.1" 200 1163
INFO [2022-06-14 07:02:39,072] - [django.server:log_message:187] "GET /login/ HTTP/1.1" 200 1163
INFO [2022-06-14 07:03:09,031] - [django.server:log_message:187] "GET /login/ HTTP/1.1" 200 1169
INFO [2022-06-14 07:03:33,260] - [django.server:log_message:187] "GET /login/ HTTP/1.1" 200 1170
INFO [2022-06-14 07:03:47,861] - [django.server:log_message:187] "GET /login/ HTTP/1.1" 200 1171
INFO [2022-06-14 07:04:53,049] - [django.server:log_message:187] "GET /login/ HTTP/1.1" 200 1178
INFO [2022-06-14 07:05:17,946] - [django.server:log_message:187] "GET /login/ HTTP/1.1" 200 1169
INFO [2022-06-14 07:05:31,504] - [django.server:log_message:187] "GET /login/ HTTP/1.1" 200 1172
INFO [2022-06-14 07:06:03,642] - [django.server:log_message:187] "GET /login/ HTTP/1.1" 200 1180
INFO [2022-06-14 07:06:12,100] - [django.server:log_message:187] "GET /login/ HTTP/1.1" 200 1177
INFO [2022-06-14 07:06:18,537] - [django.server:log_message:187] "GET /login/ HTTP/1.1" 200 1170
INFO [2022-06-14 07:09:07,150] - [django.utils.autoreload:trigger_reload:266] /home/wartinich/Projects/voice_generator/src/users/forms.py changed, reloading.
INFO [2022-06-14 07:09:07,724] - [django.utils.autoreload:run_with_reloader:677] Watching for file changes with StatReloader
INFO [2022-06-14 07:10:16,500] - [django.utils.autoreload:trigger_reload:266] /home/wartinich/Projects/voice_generator/src/users/forms.py changed, reloading.
INFO [2022-06-14 07:10:17,125] - [django.utils.autoreload:run_with_reloader:677] Watching for file changes with StatReloader
INFO [2022-06-14 07:10:17,807] - [django.server:log_message:187] "GET /login/ HTTP/1.1" 200 1234
INFO [2022-06-14 07:12:06,441] - [django.server:log_message:187] "GET /login/ HTTP/1.1" 200 1201
INFO [2022-06-14 07:13:14,635] - [django.server:log_message:187] "GET /login/ HTTP/1.1" 200 1204
INFO [2022-06-14 07:13:32,556] - [django.server:log_message:187] "GET /login/ HTTP/1.1" 200 1200
INFO [2022-06-14 07:16:48,135] - [django.server:log_message:187] "GET /login/ HTTP/1.1" 200 1209
INFO [2022-06-14 07:23:48,560] - [django.server:log_message:187] "GET /login/ HTTP/1.1" 200 1232
INFO [2022-06-14 07:24:02,324] - [django.server:log_message:187] "GET /login/ HTTP/1.1" 200 1239
INFO [2022-06-14 07:24:17,164] - [django.server:log_message:187] "GET /login/ HTTP/1.1" 200 1235
INFO [2022-06-14 07:24:38,721] - [django.server:log_message:187] "GET /login/ HTTP/1.1" 200 1240
INFO [2022-06-14 07:24:52,065] - [django.server:log_message:187] "GET /login/ HTTP/1.1" 200 1245
INFO [2022-06-14 07:27:29,487] - [django.server:log_message:187] "GET /login/ HTTP/1.1" 200 1411
INFO [2022-06-14 07:29:22,864] - [django.server:log_message:187] "GET /login/ HTTP/1.1" 200 1475
INFO [2022-06-14 07:29:33,032] - [django.server:log_message:187] "GET /login/ HTTP/1.1" 200 1481
INFO [2022-06-14 07:29:43,854] - [django.server:log_message:187] "GET /login/ HTTP/1.1" 200 1472
INFO [2022-06-14 07:29:45,022] - [django.server:log_message:187] "GET /login/ HTTP/1.1" 200 1472
INFO [2022-06-14 07:30:17,650] - [django.server:log_message:187] "GET /login/ HTTP/1.1" 200 1473
INFO [2022-06-14 07:31:05,527] - [django.server:log_message:187] "GET /login/ HTTP/1.1" 200 1447
INFO [2022-06-14 07:31:06,386] - [django.server:log_message:187] "GET /login/ HTTP/1.1" 200 1447
INFO [2022-06-14 07:32:38,630] - [django.server:log_message:187] "GET /login/ HTTP/1.1" 200 1498
INFO [2022-06-14 07:32:39,359] - [django.server:log_message:187] "GET /login/ HTTP/1.1" 200 1498
INFO [2022-06-14 07:32:39,549] - [django.server:log_message:187] "GET /login/ HTTP/1.1" 200 1498
INFO [2022-06-14 07:32:56,516] - [django.server:log_message:187] "GET /login/ HTTP/1.1" 200 1500
INFO [2022-06-14 07:32:57,126] - [django.server:log_message:187] "GET /login/ HTTP/1.1" 200 1500
INFO [2022-06-14 07:32:57,292] - [django.server:log_message:187] "GET /login/ HTTP/1.1" 200 1500
INFO [2022-06-14 07:32:57,461] - [django.server:log_message:187] "GET /login/ HTTP/1.1" 200 1500
INFO [2022-06-14 07:32:57,650] - [django.server:log_message:187] "GET /login/ HTTP/1.1" 200 1500
INFO [2022-06-14 07:33:07,899] - [django.server:log_message:187] "GET /login/ HTTP/1.1" 200 1465
INFO [2022-06-14 07:33:33,921] - [django.server:log_message:187] "GET /login/ HTTP/1.1" 200 1506
INFO [2022-06-14 07:33:35,328] - [django.server:log_message:187] "GET /login/ HTTP/1.1" 200 1506
INFO [2022-06-14 07:34:16,522] - [django.server:log_message:187] "GET /login/ HTTP/1.1" 200 1495
INFO [2022-06-14 07:35:18,237] - [django.server:log_message:187] "GET /login/ HTTP/1.1" 200 1474
INFO [2022-06-14 07:35:51,219] - [django.server:log_message:187] "GET /login/ HTTP/1.1" 200 1470
INFO [2022-06-14 07:36:11,819] - [django.server:log_message:187] "GET /login/ HTTP/1.1" 200 1470
INFO [2022-06-14 07:36:50,851] - [django.server:log_message:187] "GET /login/ HTTP/1.1" 200 1475
INFO [2022-06-14 07:36:51,808] - [django.server:log_message:187] "GET /login/ HTTP/1.1" 200 1475
INFO [2022-06-14 07:37:08,548] - [django.server:log_message:187] "GET /login/ HTTP/1.1" 200 1475
INFO [2022-06-14 07:37:16,793] - [django.server:log_message:187] "GET /login/ HTTP/1.1" 200 1474
INFO [2022-06-14 07:37:28,806] - [django.server:log_message:187] "GET /login/ HTTP/1.1" 200 1474
INFO [2022-06-14 07:43:36,523] - [django.server:log_message:187] "GET /login/ HTTP/1.1" 200 1478
INFO [2022-06-14 07:44:02,634] - [django.server:log_message:187] "GET /login/ HTTP/1.1" 200 1486
INFO [2022-06-14 07:44:24,756] - [django.server:log_message:187] "GET /login/ HTTP/1.1" 200 1486
INFO [2022-06-14 07:45:13,697] - [django.server:log_message:187] "GET /login/ HTTP/1.1" 200 1497
INFO [2022-06-14 07:46:05,626] - [django.server:log_message:187] "GET /login/ HTTP/1.1" 200 1505
INFO [2022-06-14 07:46:34,625] - [django.server:log_message:187] "GET /login/ HTTP/1.1" 200 1518
INFO [2022-06-14 07:47:02,519] - [django.utils.autoreload:trigger_reload:266] /home/wartinich/Projects/voice_generator/src/users/forms.py changed, reloading.
INFO [2022-06-14 07:47:03,178] - [django.utils.autoreload:run_with_reloader:677] Watching for file changes with StatReloader
INFO [2022-06-14 07:47:04,644] - [django.server:log_message:187] "GET /login/ HTTP/1.1" 200 1521
INFO [2022-06-14 07:48:31,593] - [django.server:log_message:187] "GET /login/ HTTP/1.1" 200 1577
INFO [2022-06-14 07:48:47,638] - [django.server:log_message:187] "GET /login/ HTTP/1.1" 200 1575
INFO [2022-06-14 07:48:56,197] - [django.server:log_message:187] "GET /login/ HTTP/1.1" 200 1575
INFO [2022-06-14 07:49:03,599] - [django.server:log_message:187] "GET /login/ HTTP/1.1" 200 1575
INFO [2022-06-14 07:49:12,714] - [django.server:log_message:187] "GET /login/ HTTP/1.1" 200 1579
INFO [2022-06-14 07:49:22,500] - [django.server:log_message:187] "GET /login/ HTTP/1.1" 200 1579
INFO [2022-06-14 07:49:51,214] - [django.server:log_message:187] "GET /login/ HTTP/1.1" 200 1585
INFO [2022-06-14 07:50:00,778] - [django.server:log_message:187] "GET /login/ HTTP/1.1" 200 1585
INFO [2022-06-14 07:50:34,021] - [django.server:log_message:187] "GET /login/ HTTP/1.1" 200 1587
INFO [2022-06-14 07:50:44,788] - [django.server:log_message:187] "GET /login/ HTTP/1.1" 200 1595
INFO [2022-06-14 07:51:24,415] - [django.server:log_message:187] "GET /login/ HTTP/1.1" 200 1596
INFO [2022-06-14 07:51:35,384] - [django.server:log_message:187] "GET /login/ HTTP/1.1" 200 1596
INFO [2022-06-14 07:52:06,120] - [django.server:log_message:187] "GET /login/ HTTP/1.1" 200 1616
INFO [2022-06-14 07:52:14,853] - [django.server:log_message:187] "GET /login/ HTTP/1.1" 200 1618
INFO [2022-06-14 07:52:20,292] - [django.server:log_message:187] "GET /login/ HTTP/1.1" 200 1616
INFO [2022-06-14 07:52:32,188] - [django.server:log_message:187] "GET /login/ HTTP/1.1" 200 1616
INFO [2022-06-14 07:53:11,530] - [django.server:log_message:187] "GET /login/ HTTP/1.1" 200 1604
INFO [2022-06-14 07:53:33,994] - [django.server:log_message:187] "GET /login/ HTTP/1.1" 200 1617
INFO [2022-06-14 07:53:57,263] - [django.server:log_message:187] "GET /login/ HTTP/1.1" 200 1616
INFO [2022-06-14 07:54:15,097] - [django.server:log_message:187] "GET /login/ HTTP/1.1" 200 1616
INFO [2022-06-14 07:54:20,989] - [django.server:log_message:187] "GET /login/ HTTP/1.1" 200 1616
INFO [2022-06-14 07:57:14,513] - [django.server:log_message:187] "GET /login/ HTTP/1.1" 200 1641
INFO [2022-06-14 07:57:15,981] - [django.server:log_message:187] "GET /sign_up/ HTTP/1.1" 200 1973
